Workbook
Name Income_01: '1'!$C$20:$D$23,'1'!$C$25:$D$25
Name סוג_הוצאה: Dropdown!$B$2:$B$100
Name סוג_תשלום: Dropdown!$A$2:$A$24
Name קטגוריה: Dropdown!$C$2:$C$100
Name קטגוריה_2: [1]Dropdown!$C$2:$C$13
Name קטגוריה_3: Dropdown!$E$2:$E$13
Name קטגוריה_4: Dropdown!$F$2:$F$14
Name קטגוריה_5: Dropdown!$G$2:$G$14
Name קטגוריה_6: Dropdown!$H$2:$H$7
Name קטגוריה_7: Dropdown!$I$2:$I$10
Name קטגוריה_8: Dropdown!$J$1:$J$11
Name קטגוריה_8__עסק: Dropdown!$J$1:$J$11

Sheet Dropdown
A1: אמצעי | B1: קטגוריה 1: תחזוקת דירה ותקשורת | C1: קטגוריה 2: מזון וקניות | D1: קטגוריה 2: מזון וקניות | E1: קטגוריה 3: רכב ונסיעות | F1: קטגוריה 4: ילדים וחינוך | G1: קטגוריה 5: תרבות ופנאי | H1: קטגוריה 6: בריאות וטיפולים | I1: קטגוריה 7: ביטוחים ופיננסים | J1: קטגוריה 8: עסק | M1: משכנתא
A2: ל-ו 1 | B2: משכנתא | C2: תחזוקת דירה ותקשורת | D2: תחזוקת דירה ותקשורת | E2: דלק | F2: גנים | G2: חופשות בחו"ל | H2: קופ"ח + משלים | I2: תוכניות חסכון | J2: מע"מ | M2: שכר דירה
A3: ל-ו 2 | B3: שכר דירה | C3: תחזוקת דירה ותקשורת | D3: מזון וקניות | E3: טיפולים ותיקונים | F3: בתי ספר | G3: חופשות בארץ | H3: ביטוח בריאות פרטי | I3: קופות גמל | J3: מס הכנסה | M3: ארנונה
A4: י-ק 1 | B4: ארנונה | C4: תחזוקת דירה ותקשורת | D4: רכב ונסיעות | E4: אגרות (כולל טסט) | F4: אוניברסיטה | G4: מועדוני ספורט ובריאות | H4: רופאים מקצועיים | I4: ניירות ערך | J4: קרן השתלמות | M4: מים
A5: י-ק 2 | B5: מים | C5: תחזוקת דירה ותקשורת | D5: ילדים וחינוך | E5: ביטוח רכב | F5: ספרים ועזרי לימוד | G5: מסעדות ומשלוחים | H5: תרופות | I5: ביטוחי חיים (ריסק) | J5: פנסיה | M5: חשמל
A6: י-מ 1 | B6: חשמל | C6: תחזוקת דירה ותקשורת | D6: תרבות ופנאי | E6: חניה | F6: שיעורים פרטיים | G6: בילוים | H6: טיפול | I6: ביטוחים אחרים | J6: ביטוח לאומי | M6: גז/נפט
A7: י-מ 2 | B7: גז/נפט | C7: תחזוקת דירה ותקשורת | D7: בריאות וטיפולים | E7: מוניות | F7: תחבורה ונסיעות | G7: אוכל יניב | H7: אחר | I7: החזר הלוואות | J7: רו"ח | M7: טלפון (נייח)
A8: ל-ח 1 | B8: טלפון (נייח) | C8: תחזוקת דירה ותקשורת | D8: ביטוחים ופיננסים | E8: רכישות לאוטו | F8: חוגים וקייטנות | G8: אוכל לילי | I8: עמלות | J8: שיווק | M8: טלפונים ניידים
A9: ל-ח 2 | B9: טלפונים ניידים | C9: תחזוקת דירה ותקשורת | D9: עסק | E9: קנסות ותשלומים | F9: מטפלת / שמרטף | G9: עיתונים ומנויים שונים | I9: ריבית עו"ש | J9: הוצאות שוטפות | M9: ביוב
A10: ל-ל 1 | B10: ביוב | C10: תחזוקת דירה ותקשורת | E10: השכרת רכב | F10: צעצועים ומתנות | G10: אירועים ומתנות | I10: תרומות | J10: רכישות לעסק | M10: כבלים
A11: ל-ל 2 | B11: כבלים | C11: תחזוקת דירה ותקשורת | E11: תחבורה ציבורית | F11: מוצרי תינוקות | G11: לימודים וקורסים | J11: משכורת | M11: אינטרנט
A12: ל-פ 1 | B12: אינטרנט | C12: תחזוקת דירה ותקשורת | E12: אגרות כבישים | F12: דמי כיס | G12: בילוי בחול | M12: ועד בית/ישוב
A13: ל-פ 2 | B13: ועד בית/ישוב | C13: תחזוקת דירה ותקשורת | E13: אחר | F13: ריהוט ומצרכים | G13: אחר | M13: עוזרת בית
A14: העברה | B14: עוזרת בית | C14: תחזוקת דירה ותקשורת | F14: אחר | G14: אחר | M14: גינון
A15: מזומן | B15: גינון | C15: תחזוקת דירה ותקשורת | M15: ביטוח דירה
A16: הל-ד | B16: ביטוח דירה | C16: תחזוקת דירה ותקשורת | M16: רכישות לבית
A17: הל-ה | B17: רכישות לבית | C17: תחזוקת דירה ותקשורת | M17: אחזקת בית ותיקונים
A18: חש-ד | B18: אחזקת בית ותיקונים | C18: תחזוקת דירה ותקשורת | M18: מנויים דיגטליים
A19: חש-ה | B19: מנויים דיגטליים | C19: תחזוקת דירה ותקשורת | M19: אחר
A20: הל-ל | B20: בנייה | C20: תחזוקת דירה ותקשורת | M20: סך דירה ותקשורת
A21: חש-ל | B21: מזון וטואלטיקה | C21: מזון וקניות | M21: מזון וטואלטיקה
A22: צ'ק | B22: סיגריות | C22: מזון וקניות | M22: סיגריות
A23: 10ביס | B23: טיפוח ויופי | C23: מזון וקניות | M23: טיפוח ויופי
A24: י-ח | B24: קוסמטיקה | C24: מזון וקניות | M24: קוסמטיקה
B25: ביגוד והנעלה | C25: מזון וקניות | M25: ביגוד והנעלה
B26: קניות שונות | C26: מזון וקניות | M26: קניות שונות
B27: מזומן ללא מעקב | C27: מזון וקניות | M27: מזומן ללא מעקב
B28: בר מים | C28: מזון וקניות | M28: בר מים
B29: מכשירים | C29: מזון וקניות | M29: מכשירים
B30: הוצאות לעסק | C30: מזון וקניות | M30: הוצאות לעסק
B31: מנויים | C31: מזון וקניות | M31: אחר
B32: תוכנות מחשב | C32: מזון וקניות | M32: אחר
B33: דלק | C33: רכב ונסיעות | M33: סך מזון וקניות
B34: טיפולים ותיקונים | C34: רכב ונסיעות | M34: דלק
B35: אגרות (כולל טסט) | C35: רכב ונסיעות | M35: טיפולים ותיקונים
B36: ביטוח רכב | C36: רכב ונסיעות | M36: אגרות (כולל טסט)
... B95: משכורת | C95: עסק | M95: פנסיה
M96: ביטוח לאומי
M97: רו"ח
M98: שיווק
...

Sheet פרטים
A2: שם משפחה | C2: שם פרטי | E2: מקצוע
A4: שם משפחה | C4: שם פרטי | E4: מקצוע

Sheet Data
C1: מדרגה 1 | D1: ריבית מתואמת 1 | E1: מדרגה 2 | F1: ריבית מתואמת 2
A2: מסגרת אשראי דיסקונט | B2: 35000 | C2: 0-29000 | D2: 3.13 | E2: 29000.01-35000 | F2: 10.55
A3: מסגרת אשראי הפועלים | B3: 10000
A6: הלוואות | B6: סוג | C6: ריבית | D6: תאריך סיום | E6: סכום התחלתי | F6: החזר חודשי | K6: נשאר להחזיר
A7: הפועלים | B7: רגילה | C7: P+1.35% | D7: 15.11.2022 | E7: 55000 | F7: 1100 | H7: משתנה | I7: קרן שווה | J7: לא צמודה | K7: 28573.32
A8: דיסקונט | B8: רגילה | C8: P+1.5% | D8: 05.05.2020 | E8: 40000 | F8: 747 | H8: משתנה | I8: קרן שווה | J8: לא צמודה | K8: 28066
A9: קרמר אדי ויידה | B9: רגילה | C9: 0 | K9: 38550
A10: סבא | B10: רגילה | C10: 0 | K10: 80000 | L10: 20000 יורו
A11: דיסקונט | B11: משכנתא | C11: P+1.2% | D11: 15.07.2041 | E11: 233000 | F11: 1327 | G11: פריים | H11: משתנה | I11: קרן שווה | J11: לא צמודה | K11: 230227
A12: דיסקונט | B12: משכנתא | C12: 0.0482 | D12: 15.07.2036 | E12: 234000 | F12: 1521 | G12: קל"צ | H12: קבועה | I12: שפיצר | J12: לא צמודה | K12: 232250
A13: דיסקונט | B13: משכנתא | C13: 0.036 | D13: 15.07.2041 | E13: 233000 | F13: 1179 | G13: קבועה צמוד | H13: קבועה | I13: שפיצר | J13: צמודה | K13: 233035
A17: פקדונות

Sheet נכסים והתחיבויות
A1: הלוואות ופקדונות | B1: סוג | C1: 12-17 | D1: 01 | E1: 02 | F1: 03 | G1: 04 | H1: 05 | I1: 06 | J1: 07 | K1: 08 | L1: 09 | M1: 10 | N1: 11 | O1: 12 | Q1: מצב נוכחי | R1: רגילה | S1: משכנתא | T1: פקדון | U1: חסכון | V1: קרן השתלמות | W1: נכסים
A2: הפועלים | B2: רגילה | Q2: 12-16 | R2: =SUMIF($B:$B,$R$1,$C:$C) -> 0 | S2: =SUMIF($B:$B,$S$1,$C:$C) -> 0 | T2: =SUMIF($B:$B,$T$1,$C:$C) -> 0 | U2: =SUMIF($B:$B,$U$1,$C:$C) -> 0 | V2: =SUMIF($B:$B,$V$1,$C:$C) -> 0 | W2: 1500000
A3: הפועלים | B3: רגילה | Q3: 01 | R3: =SUMIF($B:$B,$R$1,$D:$D) -> 0 | S3: =SUMIF($B:$B,S$1,$D:$D) -> 0 | T3: =SUMIF($B:$B,$T$1,$D:$D) -> 0 | U3: =SUMIF($B:$B,$U$1,$D:$D) -> 0 | V3: =SUMIF($B:$B,$V$1,$D:$D) -> 0 | W3: 1500000
A4: דיסקונט | B4: רגילה | Q4: 02 | R4: =SUMIF($B:$B,$R$1,$E:$E) -> 0 | S4: =SUMIF($B:$B,S$1,$E:$E) -> 0 | T4: =SUMIF($B:$B,$T$1,$E:$E) -> 0 | U4: =SUMIF($B:$B,$U$1,$E:$E) -> 0 | V4: =SUMIF($B:$B,$V$1,$E:$E) -> 0 | W4: 1500000
A5: אדי ויידה | B5: רגילה | Q5: 03 | R5: =SUMIF($B:$B,$R$1,$F:$F) -> 0 | S5: =SUMIF($B:$B,S$1,$F:$F) -> 0 | T5: =SUMIF($B:$B,$T$1,$F:$F) -> 0 | U5: =SUMIF($B:$B,$U$1,$F:$F) -> 0 | V5: =SUMIF($B:$B,$V$1,$F:$F) -> 0 | W5: 1500000
A6: סבא | B6: רגילה | Q6: 04 | R6: =SUMIF($B:$B,$R$1,$G:$G) -> 0 | S6: =SUMIF($B:$B,S$1,$G:$G) -> 0 | T6: =SUMIF($B:$B,$T$1,$G:$G) -> 0 | U6: =SUMIF($B:$B,$U$1,$G:$G) -> 0 | V6: =SUMIF($B:$B,$V$1,$G:$G) -> 0 | W6: 1500000
A7: דיסקונט | B7: משכנתא | Q7: 05 | R7: =SUMIF($B:$B,$R$1,$H:$H) -> 0 | S7: =SUMIF($B:$B,S$1,$H:$H) -> 0 | T7: =SUMIF($B:$B,$T$1,$H:$H) -> 0 | U7: =SUMIF($B:$B,$U$1,$H:$H) -> 0 | V7: =SUMIF($B:$B,$V$1,$H:$H) -> 0 | W7: 1500000
A8: דיסקונט | B8: משכנתא | Q8: 06 | R8: =SUMIF($B:$B,$R$1,$I:$I) -> 0 | S8: =SUMIF($B:$B,S$1,$I:$I) -> 0 | T8: =SUMIF($B:$B,$T$1,$I:$I) -> 0 | U8: =SUMIF($B:$B,$U$1,$I:$I) -> 0 | V8: =SUMIF($B:$B,$V$1,$I:$I) -> 0 | W8: 1500000
A9: דיסקונט | B9: משכנתא | Q9: 07 | R9: =SUMIF($B:$B,$R$1,$J:$J) -> 0 | S9: =SUMIF($B:$B,S$1,$J:$J) -> 0 | T9: =SUMIF($B:$B,$T$1,$J:$J) -> 0 | U9: =SUMIF($B:$B,$U$1,$J:$J) -> 0 | V9: =SUMIF($B:$B,$V$1,$J:$J) -> 0 | W9: 1500000
A10: שורקות | B10: פקדון | Q10: 08 | R10: =SUMIF($B:$B,$R$1,$K:$K) -> 0 | S10: =SUMIF($B:$B,S$1,$K:$K) -> 0 | T10: =SUMIF($B:$B,$T$1,$K:$K) -> 0 | U10: =SUMIF($B:$B,$U$1,$K:$K) -> 0 | V10: =SUMIF($B:$B,$V$1,$K:$K) -> 0 | W10: 1500000
A11: תופים | B11: פקדון | Q11: 09 | R11: =SUMIF($B:$B,$R$1,$L:$L) -> 0 | S11: =SUMIF($B:$B,S$1,$L:$L) -> 0 | T11: =SUMIF($B:$B,$T$1,$L:$L) -> 0 | U11: =SUMIF($B:$B,$U$1,$L:$L) -> 0 | V11: =SUMIF($B:$B,$V$1,$L:$L) -> 0 | W11: 1500000
A12: בית (אורן+מיכה) | B12: פקדון | Q12: 10 | R12: =SUMIF($B:$B,$R$1,$M:$M) -> 0 | S12: =SUMIF($B:$B,S$1,$M:$M) -> 0 | T12: =SUMIF($B:$B,$T$1,$M:$M) -> 0 | U12: =SUMIF($B:$B,$U$1,$M:$M) -> 0 | V12: =SUMIF($B:$B,$V$1,$M:$M) -> 0 | W12: 1500000
A13: בית2 | B13: פקדון | Q13: 11 | R13: =SUMIF($B:$B,$R$1,$N:$N) -> 0 | S13: =SUMIF($B:$B,S$1,$N:$N) -> 0 | T13: =SUMIF($B:$B,$T$1,$N:$N) -> 0 | U13: =SUMIF($B:$B,$U$1,$N:$N) -> 0 | V13: =SUMIF($B:$B,$V$1,$N:$N) -> 0 | W13: 1500000
A14: משכנתא | B14: פקדון | Q14: 12 | R14: =SUMIF($B:$B,$R$1,$O:$O) -> 0 | S14: =SUMIF($B:$B,S$1,$O:$O) -> 0 | T14: =SUMIF($B:$B,$T$1,$O:$O) -> 0 | U14: =SUMIF($B:$B,$U$1,$O:$O) -> 0 | V14: =SUMIF($B:$B,$V$1,$O:$O) -> 0 | W14: 1500000

Sheet 1125
A1: 12 | B1: 10 | C1: דיסקונט | D1: לאומי | F1: תאריך | G1: סכום | H1: סוג הוצאה | I1: קטגוריה | J1: איך | K1: # | L1: סיום | N1: בלת"ם
A2: כרטיסי אשראי | B2: כ"א לאומי לילי | C2: 18534.2 | D2: 0 | F2: קבועות
B3: כ"א לאומי לילי חו"ל | C3: 578.88 | G3: 10 | H3: עמלות | I3: =_xlfn.XLOOKUP(H3,[2]Dropdown!B:B,[2]Dropdown!C:C) -> ביטוחים ופיננסים | J3: חש-ל
B4: כ"א קאל יניב | C4: 8037.61 | D4: 20894.74 | G4: 0 | H4: ביוב | I4: =_xlfn.XLOOKUP(H4,[2]Dropdown!B:B,[2]Dropdown!C:C) -> תחזוקת דירה ותקשורת | J4: ל-ו 2
G5: 0 | H5: ארנונה | I5: =_xlfn.XLOOKUP(H5,[2]Dropdown!B:B,[2]Dropdown!C:C) -> תחזוקת דירה ותקשורת | J5: ל-ו 2 | Q5: קבוע | R5: 1 | S5: 2 | T5: 3 | U5: 4 | V5: 5 | W5: 6 | X5: 7 | Y5: 8 | Z5: 9 | AA5: 10 | AB5: 11 | AC5: 12 | AD5: 13 | AE5: 14 | AF5: 15 | AG5: 16 | AH5: 17 | AI5: 18 | AJ5: 19 | AK5: 20 | AL5: 21 | AM5: 22 | AN5: 23 | AO5: 24 | AP5: 25 | AQ5: 26 | AR5: 27 | AS5: 28 | AT5: 29 | AU5: 30 | AV5: 31 | AW5: סה"כ
G6: 1760.4 | H6: ועד בית/ישוב | I6: =_xlfn.XLOOKUP(H6,[2]Dropdown!B:B,[2]Dropdown!C:C) -> תחזוקת דירה ותקשורת | J6: העברה | P6: תחזוקת דירה ותקשורת | Q6: =SUMIFS($G:$G,$I:$I,$P6,$F:$F,"") -> 10318.81 | R6: =SUMIFS($G:$G,$I:$I,$P6,$F:$F, TEXT(R$5,"00") & "." & TEXT($A$1,"00")) -> 0 | S6: =SUMIFS($G:$G,$I:$I,$P6,$F:$F, TEXT(S$5,"00") & "." & TEXT($A$1,"00")) -> 0 | T6: =SUMIFS($G:$G,$I:$I,$P6,$F:$F, TEXT(T$5,"00") & "." & TEXT($A$1,"00")) -> 0 | U6: =SUMIFS($G:$G,$I:$I,$P6,$F:$F, TEXT(U$5,"00") & "." & TEXT($A$1,"00")) -> 0 | V6: =SUMIFS($G:$G,$I:$I,$P6,$F:$F, TEXT(V$5,"00") & "." & TEXT($A$1,"00")) -> 0 | W6: =SUMIFS($G:$G,$I:$I,$P6,$F:$F, TEXT(W$5,"00") & "." & TEXT($A$1,"00")) -> 0 | X6: =SUMIFS($G:$G,$I:$I,$P6,$F:$F, TEXT(X$5,"00") & "." & TEXT($A$1,"00")) -> 0 | Y6: =SUMIFS($G:$G,$I:$I,$P6,$F:$F, TEXT(Y$5,"00") & "." & TEXT($A$1,"00")) -> 0 | ... AV6: =SUMIFS($G:$G,$I:$I,$P6,$F:$F, TEXT(AV$5,"00") & "." & TEXT($A$1,"00")) -> 0 | AW6: =SUM(Q6:AV6) -> 10318.81
A7: הלוואה | B7: הלוואה | C7: 0 | D7: 0 | G7: 0 | H7: טלפון (נייח) | I7: =_xlfn.XLOOKUP(H7,[2]Dropdown!B:B,[2]Dropdown!C:C) -> תחזוקת דירה ותקשורת | J7: העברה | P7: מזון וקניות | Q7: =SUMIFS($G:$G,$I:$I,$P7,$F:$F,"") -> 2432.66 | R7: =SUMIFS($G:$G,$I:$I,$P7,$F:$F, TEXT(R$5,"00") & "." & TEXT($A$1,"00")) -> 0 | S7: =SUMIFS($G:$G,$I:$I,$P7,$F:$F, TEXT(S$5,"00") & "." & TEXT($A$1,"00")) -> 0 | T7: =SUMIFS($G:$G,$I:$I,$P7,$F:$F, TEXT(T$5,"00") & "." & TEXT($A$1,"00")) -> 0 | U7: =SUMIFS($G:$G,$I:$I,$P7,$F:$F, TEXT(U$5,"00") & "." & TEXT($A$1,"00")) -> 0 | V7: =SUMIFS($G:$G,$I:$I,$P7,$F:$F, TEXT(V$5,"00") & "." & TEXT($A$1,"00")) -> 0 | W7: =SUMIFS($G:$G,$I:$I,$P7,$F:$F, TEXT(W$5,"00") & "." & TEXT($A$1,"00")) -> 0 | X7: =SUMIFS($G:$G,$I:$I,$P7,$F:$F, TEXT(X$5,"00") & "." & TEXT($A$1,"00")) -> 0 | Y7: =SUMIFS($G:$G,$I:$I,$P7,$F:$F, TEXT(Y$5,"00") & "." & TEXT($A$1,"00")) -> 0 | ... AV7: =SUMIFS($G:$G,$I:$I,$P7,$F:$F, TEXT(AV$5,"00") & "." & TEXT($A$1,"00")) -> 0 | AW7: =SUM(Q7:AV7) -> 2432.66
B8: משכנתא | C8: 4642.05 | G8: 95 | H8: אינטרנט | I8: =_xlfn.XLOOKUP(H8,[2]Dropdown!B:B,[2]Dropdown!C:C) -> תחזוקת דירה ותקשורת | J8: העברה | P8: רכב ונסיעות | Q8: =SUMIFS($G:$G,$I:$I,$P8,$F:$F,"") -> 588 | R8: =SUMIFS($G:$G,$I:$I,$P8,$F:$F, TEXT(R$5,"00") & "." & TEXT($A$1,"00")) -> 0 | S8: =SUMIFS($G:$G,$I:$I,$P8,$F:$F, TEXT(S$5,"00") & "." & TEXT($A$1,"00")) -> 0 | T8: =SUMIFS($G:$G,$I:$I,$P8,$F:$F, TEXT(T$5,"00") & "." & TEXT($A$1,"00")) -> 0 | U8: =SUMIFS($G:$G,$I:$I,$P8,$F:$F, TEXT(U$5,"00") & "." & TEXT($A$1,"00")) -> 0 | V8: =SUMIFS($G:$G,$I:$I,$P8,$F:$F, TEXT(V$5,"00") & "." & TEXT($A$1,"00")) -> 0 | W8: =SUMIFS($G:$G,$I:$I,$P8,$F:$F, TEXT(W$5,"00") & "." & TEXT($A$1,"00")) -> 0 | X8: =SUMIFS($G:$G,$I:$I,$P8,$F:$F, TEXT(X$5,"00") & "." & TEXT($A$1,"00")) -> 0 | Y8: =SUMIFS($G:$G,$I:$I,$P8,$F:$F, TEXT(Y$5,"00") & "." & TEXT($A$1,"00")) -> 0 | ... AV8: =SUMIFS($G:$G,$I:$I,$P8,$F:$F, TEXT(AV$5,"00") & "." & TEXT($A$1,"00")) -> 0 | AW8: =SUM(Q8:AV8) -> 588
A9: קבועים | B9: קיבוץ/שוטף | C9: 3073.4 | D9: 1696.61 | G9: 112 | H9: קופ"ח + משלים | I9: =_xlfn.XLOOKUP(H9,[2]Dropdown!B:B,[2]Dropdown!C:C) -> בריאות וטיפולים | J9: העברה | P9: ילדים וחינוך | Q9: =SUMIFS($G:$G,$I:$I,$P9,$F:$F,"") -> 3582.72 | R9: =SUMIFS($G:$G,$I:$I,$P9,$F:$F, TEXT(R$5,"00") & "." & TEXT($A$1,"00")) -> 0 | S9: =SUMIFS($G:$G,$I:$I,$P9,$F:$F, TEXT(S$5,"00") & "." & TEXT($A$1,"00")) -> 0 | T9: =SUMIFS($G:$G,$I:$I,$P9,$F:$F, TEXT(T$5,"00") & "." & TEXT($A$1,"00")) -> 0 | U9: =SUMIFS($G:$G,$I:$I,$P9,$F:$F, TEXT(U$5,"00") & "." & TEXT($A$1,"00")) -> 0 | V9: =SUMIFS($G:$G,$I:$I,$P9,$F:$F, TEXT(V$5,"00") & "." & TEXT($A$1,"00")) -> 0 | W9: =SUMIFS($G:$G,$I:$I,$P9,$F:$F, TEXT(W$5,"00") & "." & TEXT($A$1,"00")) -> 0 | X9: =SUMIFS($G:$G,$I:$I,$P9,$F:$F, TEXT(X$5,"00") & "." & TEXT($A$1,"00")) -> 0 | Y9: =SUMIFS($G:$G,$I:$I,$P9,$F:$F, TEXT(Y$5,"00") & "." & TEXT($A$1,"00")) -> 0 | ... AV9: =SUMIFS($G:$G,$I:$I,$P9,$F:$F, TEXT(AV$5,"00") & "." & TEXT($A$1,"00")) -> 0 | AW9: =SUM(Q9:AV9) -> 3582.72
B10: אחר | C10: 454.3 | G10: 387 | H10: ביטוח בריאות פרטי | I10: =_xlfn.XLOOKUP(H10,[2]Dropdown!B:B,[2]Dropdown!C:C) -> בריאות וטיפולים | J10: העברה | P10: תרבות ופנאי | Q10: =SUMIFS($G:$G,$I:$I,$P10,$F:$F,"") -> 0 | R10: =SUMIFS($G:$G,$I:$I,$P10,$F:$F, TEXT(R$5,"00") & "." & TEXT($A$1,"00")) -> 0 | S10: =SUMIFS($G:$G,$I:$I,$P10,$F:$F, TEXT(S$5,"00") & "." & TEXT($A$1,"00")) -> 0 | T10: =SUMIFS($G:$G,$I:$I,$P10,$F:$F, TEXT(T$5,"00") & "." & TEXT($A$1,"00")) -> 0 | U10: =SUMIFS($G:$G,$I:$I,$P10,$F:$F, TEXT(U$5,"00") & "." & TEXT($A$1,"00")) -> 0 | V10: =SUMIFS($G:$G,$I:$I,$P10,$F:$F, TEXT(V$5,"00") & "." & TEXT($A$1,"00")) -> 0 | W10: =SUMIFS($G:$G,$I:$I,$P10,$F:$F, TEXT(W$5,"00") & "." & TEXT($A$1,"00")) -> 0 | X10: =SUMIFS($G:$G,$I:$I,$P10,$F:$F, TEXT(X$5,"00") & "." & TEXT($A$1,"00")) -> 0 | Y10: =SUMIFS($G:$G,$I:$I,$P10,$F:$F, TEXT(Y$5,"00") & "." & TEXT($A$1,"00")) -> 0 | ... AV10: =SUMIFS($G:$G,$I:$I,$P10,$F:$F, TEXT(AV$5,"00") & "." & TEXT($A$1,"00")) -> 0 | AW10: =SUM(Q10:AV10) -> 0
A11: תשלומים | B11: עמלות | C11: 0 | D11: 10 | G11: 100 | H11: ביטוח דירה | I11: =_xlfn.XLOOKUP(H11,[2]Dropdown!B:B,[2]Dropdown!C:C) -> תחזוקת דירה ותקשורת | J11: העברה | P11: בריאות וטיפולים | Q11: =SUMIFS($G:$G,$I:$I,$P11,$F:$F,"") -> 1392.26 | R11: =SUMIFS($G:$G,$I:$I,$P11,$F:$F, TEXT(R$5,"00") & "." & TEXT($A$1,"00")) -> 0 | S11: =SUMIFS($G:$G,$I:$I,$P11,$F:$F, TEXT(S$5,"00") & "." & TEXT($A$1,"00")) -> 0 | T11: =SUMIFS($G:$G,$I:$I,$P11,$F:$F, TEXT(T$5,"00") & "." & TEXT($A$1,"00")) -> 0 | U11: =SUMIFS($G:$G,$I:$I,$P11,$F:$F, TEXT(U$5,"00") & "." & TEXT($A$1,"00")) -> 0 | V11: =SUMIFS($G:$G,$I:$I,$P11,$F:$F, TEXT(V$5,"00") & "." & TEXT($A$1,"00")) -> 0 | W11: =SUMIFS($G:$G,$I:$I,$P11,$F:$F, TEXT(W$5,"00") & "." & TEXT($A$1,"00")) -> 0 | X11: =SUMIFS($G:$G,$I:$I,$P11,$F:$F, TEXT(X$5,"00") & "." & TEXT($A$1,"00")) -> 0 | Y11: =SUMIFS($G:$G,$I:$I,$P11,$F:$F, TEXT(Y$5,"00") & "." & TEXT($A$1,"00")) -> 0 | ... AV11: =SUMIFS($G:$G,$I:$I,$P11,$F:$F, TEXT(AV$5,"00") & "." & TEXT($A$1,"00")) -> 0 | AW11: =SUM(Q11:AV11) -> 1392.26
B12: העברה בין חשבונות | D12: 14000 | G12: 0 | H12: מים | I12: =_xlfn.XLOOKUP(H12,[2]Dropdown!B:B,[2]Dropdown!C:C) -> תחזוקת דירה ותקשורת | J12: העברה | P12: ביטוחים ופיננסים | Q12: =SUMIFS($G:$G,$I:$I,$P12,$F:$F,"") -> 5104.43 | R12: =SUMIFS($G:$G,$I:$I,$P12,$F:$F, TEXT(R$5,"00") & "." & TEXT($A$1,"00")) -> 0 | S12: =SUMIFS($G:$G,$I:$I,$P12,$F:$F, TEXT(S$5,"00") & "." & TEXT($A$1,"00")) -> 0 | T12: =SUMIFS($G:$G,$I:$I,$P12,$F:$F, TEXT(T$5,"00") & "." & TEXT($A$1,"00")) -> 0 | U12: =SUMIFS($G:$G,$I:$I,$P12,$F:$F, TEXT(U$5,"00") & "." & TEXT($A$1,"00")) -> 0 | V12: =SUMIFS($G:$G,$I:$I,$P12,$F:$F, TEXT(V$5,"00") & "." & TEXT($A$1,"00")) -> 0 | W12: =SUMIFS($G:$G,$I:$I,$P12,$F:$F, TEXT(W$5,"00") & "." & TEXT($A$1,"00")) -> 0 | X12: =SUMIFS($G:$G,$I:$I,$P12,$F:$F, TEXT(X$5,"00") & "." & TEXT($A$1,"00")) -> 0 | Y12: =SUMIFS($G:$G,$I:$I,$P12,$F:$F, TEXT(Y$5,"00") & "." & TEXT($A$1,"00")) -> 0 | ... AV12: =SUMIFS($G:$G,$I:$I,$P12,$F:$F, TEXT(AV$5,"00") & "." & TEXT($A$1,"00")) -> 0 | AW12: =SUM(Q12:AV12) -> 5104.43
B13: העברה | C13: -1720 | G13: 0 | H13: חוגים וקייטנות | I13: =_xlfn.XLOOKUP(H13,[2]Dropdown!B:B,[2]Dropdown!C:C) -> ילדים וחינוך | J13: העברה | P13: עסק | Q13: =SUMIFS($G:$G,$I:$I,$P13,$F:$F,"") -> 41161.61 | R13: =SUMIFS($G:$G,$I:$I,$P13,$F:$F, TEXT(R$5,"00") & "." & TEXT($A$1,"00")) -> 0 | S13: =SUMIFS($G:$G,$I:$I,$P13,$F:$F, TEXT(S$5,"00") & "." & TEXT($A$1,"00")) -> 0 | T13: =SUMIFS($G:$G,$I:$I,$P13,$F:$F, TEXT(T$5,"00") & "." & TEXT($A$1,"00")) -> 0 | U13: =SUMIFS($G:$G,$I:$I,$P13,$F:$F, TEXT(U$5,"00") & "." & TEXT($A$1,"00")) -> 0 | V13: =SUMIFS($G:$G,$I:$I,$P13,$F:$F, TEXT(V$5,"00") & "." & TEXT($A$1,"00")) -> 0 | W13: =SUMIFS($G:$G,$I:$I,$P13,$F:$F, TEXT(W$5,"00") & "." & TEXT($A$1,"00")) -> 0 | X13: =SUMIFS($G:$G,$I:$I,$P13,$F:$F, TEXT(X$5,"00") & "." & TEXT($A$1,"00")) -> 0 | Y13: =SUMIFS($G:$G,$I:$I,$P13,$F:$F, TEXT(Y$5,"00") & "." & TEXT($A$1,"00")) -> 0 | ... AV13: =SUMIFS($G:$G,$I:$I,$P13,$F:$F, TEXT(AV$5,"00") & "." & TEXT($A$1,"00")) -> 0 | AW13: =SUM(Q13:AV13) -> 41161.61
A14: מזומן | B14: כספומט | G14: 0 | H14: חוגים וקייטנות | I14: =_xlfn.XLOOKUP(H14,[2]Dropdown!B:B,[2]Dropdown!C:C) -> ילדים וחינוך | J14: העברה
A15: שחרור פקדון | C15: -4200.3 | D15: 0 | G15: 1703.25 | H15: משכנתא | I15: =_xlfn.XLOOKUP(H15,[2]Dropdown!B:B,[2]Dropdown!C:C) -> תחזוקת דירה ותקשורת | J15: חש-ד
A16: חסכון | B16: פקדון | C16: 4000 | D16: 0 | G16: 1521.12 | H16: משכנתא | I16: =_xlfn.XLOOKUP(H16,[2]Dropdown!B:B,[2]Dropdown!C:C) -> תחזוקת דירה ותקשורת | J16: חש-ד
A17: הוצאות עתידיות | G17: 1417.68 | H17: משכנתא | I17: =_xlfn.XLOOKUP(H17,[2]Dropdown!B:B,[2]Dropdown!C:C) -> תחזוקת דירה ותקשורת | J17: חש-ד | P17: קטגוריה
A18: סך הוצאות | C18: 33400.14 | D18: 36601.35 | G18: 616.79 | H18: חשמל | I18: =_xlfn.XLOOKUP(H18,[2]Dropdown!B:B,[2]Dropdown!C:C) -> תחזוקת דירה ותקשורת | J18: י-ק 2 | P18: תחזוקת דירה ותקשורת | Q18: קבוע | R18: 1 | S18: 2 | T18: 3 | U18: 4 | V18: 5 | W18: 6 | X18: 7 | Y18: 8 | Z18: 9 | AA18: 10 | AB18: 11 | AC18: 12 | AD18: 13 | AE18: 14 | AF18: 15 | AG18: 16 | AH18: 17 | AI18: 18 | AJ18: 19 | AK18: 20 | AL18: 21 | AM18: 22 | AN18: 23 | AO18: 24 | AP18: 25 | AQ18: 26 | AR18: 27 | AS18: 28 | AT18: 29 | AU18: 30 | AV18: 31 | AW18: סה"כ
G19: 97.97 | H19: כבלים | I19: =_xlfn.XLOOKUP(H19,[2]Dropdown!B:B,[2]Dropdown!C:C) -> תחזוקת דירה ותקשורת | J19: ל-ו 2 | P19: {=_xlfn._xlws.FILTER(Dropdown!$B:$B,Dropdown!$C:$C = $P$18)} -> משכנתא | Q19: =SUMIFS($G:$G,$H:$H,$P19,$F:$F,"") -> 4642.05 | R19: =SUMIFS($G:$G,$H:$H,$P19,$F:$F,TEXT(R$5,"00") & "." & TEXT($A$1,"00")) -> 0 | S19: =SUMIFS($G:$G,$H:$H,$P19,$F:$F,TEXT(S$5,"00") & "." & TEXT($A$1,"00")) -> 0 | T19: =SUMIFS($G:$G,$H:$H,$P19,$F:$F,TEXT(T$5,"00") & "." & TEXT($A$1,"00")) -> 0 | U19: =SUMIFS($G:$G,$H:$H,$P19,$F:$F,TEXT(U$5,"00") & "." & TEXT($A$1,"00")) -> 0 | V19: =SUMIFS($G:$G,$H:$H,$P19,$F:$F,TEXT(V$5,"00") & "." & TEXT($A$1,"00")) -> 0 | W19: =SUMIFS($G:$G,$H:$H,$P19,$F:$F,TEXT(W$5,"00") & "." & TEXT($A$1,"00")) -> 0 | X19: =SUMIFS($G:$G,$H:$H,$P19,$F:$F,TEXT(X$5,"00") & "." & TEXT($A$1,"00")) -> 0 | Y19: =SUMIFS($G:$G,$H:$H,$P19,$F:$F,TEXT(Y$5,"00") & "." & TEXT($A$1,"00")) -> 0 | ... AV19: =SUMIFS($G:$G,$H:$H,$P19,$F:$F,TEXT(AV$5,"00") & "." & TEXT($A$1,"00")) -> 0 | AW19: =SUM(Q19:AV19) -> 4642.05
A20: הכנסות | B20: משכורת יניב | C20: 15004.26 | D20: 0 | G20: 69.9 | H20: כבלים | I20: =_xlfn.XLOOKUP(H20,[2]Dropdown!B:B,[2]Dropdown!C:C) -> תחזוקת דירה ותקשורת | J20: ל-ח 1 | P20: שכר דירה | Q20: =SUMIFS($G:$G,$H:$H,$P20,$F:$F,"") -> 0 | R20: =SUMIFS($G:$G,$H:$H,$P20,$F:$F,TEXT(R$5,"00") & "." & TEXT($A$1,"00")) -> 0 | S20: =SUMIFS($G:$G,$H:$H,$P20,$F:$F,TEXT(S$5,"00") & "." & TEXT($A$1,"00")) -> 0 | T20: =SUMIFS($G:$G,$H:$H,$P20,$F:$F,TEXT(T$5,"00") & "." & TEXT($A$1,"00")) -> 0 | U20: =SUMIFS($G:$G,$H:$H,$P20,$F:$F,TEXT(U$5,"00") & "." & TEXT($A$1,"00")) -> 0 | V20: =SUMIFS($G:$G,$H:$H,$P20,$F:$F,TEXT(V$5,"00") & "." & TEXT($A$1,"00")) -> 0 | W20: =SUMIFS($G:$G,$H:$H,$P20,$F:$F,TEXT(W$5,"00") & "." & TEXT($A$1,"00")) -> 0 | X20: =SUMIFS($G:$G,$H:$H,$P20,$F:$F,TEXT(X$5,"00") & "." & TEXT($A$1,"00")) -> 0 | Y20: =SUMIFS($G:$G,$H:$H,$P20,$F:$F,TEXT(Y$5,"00") & "." & TEXT($A$1,"00")) -> 0 | ... AV20: =SUMIFS($G:$G,$H:$H,$P20,$F:$F,TEXT(AV$5,"00") & "." & TEXT($A$1,"00")) -> 0 | AW20: =SUM(Q20:AV20) -> 0
B21: משכורת לילי | C21: 14000 | D21: 42731 | G21: 122.4 | H21: טלפונים ניידים | I21: =_xlfn.XLOOKUP(H21,[2]Dropdown!B:B,[2]Dropdown!C:C) -> תחזוקת דירה ותקשורת | J21: ל-ו 2 | P21: ארנונה | Q21: =SUMIFS($G:$G,$H:$H,$P21,$F:$F,"") -> 0 | R21: =SUMIFS($G:$G,$H:$H,$P21,$F:$F,TEXT(R$5,"00") & "." & TEXT($A$1,"00")) -> 0 | S21: =SUMIFS($G:$G,$H:$H,$P21,$F:$F,TEXT(S$5,"00") & "." & TEXT($A$1,"00")) -> 0 | T21: =SUMIFS($G:$G,$H:$H,$P21,$F:$F,TEXT(T$5,"00") & "." & TEXT($A$1,"00")) -> 0 | U21: =SUMIFS($G:$G,$H:$H,$P21,$F:$F,TEXT(U$5,"00") & "." & TEXT($A$1,"00")) -> 0 | V21: =SUMIFS($G:$G,$H:$H,$P21,$F:$F,TEXT(V$5,"00") & "." & TEXT($A$1,"00")) -> 0 | W21: =SUMIFS($G:$G,$H:$H,$P21,$F:$F,TEXT(W$5,"00") & "." & TEXT($A$1,"00")) -> 0 | X21: =SUMIFS($G:$G,$H:$H,$P21,$F:$F,TEXT(X$5,"00") & "." & TEXT($A$1,"00")) -> 0 | Y21: =SUMIFS($G:$G,$H:$H,$P21,$F:$F,TEXT(Y$5,"00") & "." & TEXT($A$1,"00")) -> 0 | ... AV21: =SUMIFS($G:$G,$H:$H,$P21,$F:$F,TEXT(AV$5,"00") & "." & TEXT($A$1,"00")) -> 0 | AW21: =SUM(Q21:AV21) -> 0
B22: קצבה | C22: 269 | G22: 80.94 | H22: ביטוח בריאות פרטי | I22: =_xlfn.XLOOKUP(H22,[2]Dropdown!B:B,[2]Dropdown!C:C) -> בריאות וטיפולים | J22: ל-ו 2 | M22: מנורה | P22: מים | Q22: =SUMIFS($G:$G,$H:$H,$P22,$F:$F,"") -> 0 | R22: =SUMIFS($G:$G,$H:$H,$P22,$F:$F,TEXT(R$5,"00") & "." & TEXT($A$1,"00")) -> 0 | S22: =SUMIFS($G:$G,$H:$H,$P22,$F:$F,TEXT(S$5,"00") & "." & TEXT($A$1,"00")) -> 0 | T22: =SUMIFS($G:$G,$H:$H,$P22,$F:$F,TEXT(T$5,"00") & "." & TEXT($A$1,"00")) -> 0 | U22: =SUMIFS($G:$G,$H:$H,$P22,$F:$F,TEXT(U$5,"00") & "." & TEXT($A$1,"00")) -> 0 | V22: =SUMIFS($G:$G,$H:$H,$P22,$F:$F,TEXT(V$5,"00") & "." & TEXT($A$1,"00")) -> 0 | W22: =SUMIFS($G:$G,$H:$H,$P22,$F:$F,TEXT(W$5,"00") & "." & TEXT($A$1,"00")) -> 0 | X22: =SUMIFS($G:$G,$H:$H,$P22,$F:$F,TEXT(X$5,"00") & "." & TEXT($A$1,"00")) -> 0 | Y22: =SUMIFS($G:$G,$H:$H,$P22,$F:$F,TEXT(Y$5,"00") & "." & TEXT($A$1,"00")) -> 0 | ... AV22: =SUMIFS($G:$G,$H:$H,$P22,$F:$F,TEXT(AV$5,"00") & "." & TEXT($A$1,"00")) -> 0 | AW22: =SUM(Q22:AV22) -> 0
B23: עסק | C23: 2280 | G23: 10.42 | H23: ביטוח בריאות פרטי | I23: =_xlfn.XLOOKUP(H23,[2]Dropdown!B:B,[2]Dropdown!C:C) -> בריאות וטיפולים | J23: ל-ו 2 | M23: הראל | P23: חשמל | Q23: =SUMIFS($G:$G,$H:$H,$P23,$F:$F,"") -> 616.79 | R23: =SUMIFS($G:$G,$H:$H,$P23,$F:$F,TEXT(R$5,"00") & "." & TEXT($A$1,"00")) -> 0 | S23: =SUMIFS($G:$G,$H:$H,$P23,$F:$F,TEXT(S$5,"00") & "." & TEXT($A$1,"00")) -> 0 | T23: =SUMIFS($G:$G,$H:$H,$P23,$F:$F,TEXT(T$5,"00") & "." & TEXT($A$1,"00")) -> 0 | U23: =SUMIFS($G:$G,$H:$H,$P23,$F:$F,TEXT(U$5,"00") & "." & TEXT($A$1,"00")) -> 0 | V23: =SUMIFS($G:$G,$H:$H,$P23,$F:$F,TEXT(V$5,"00") & "." & TEXT($A$1,"00")) -> 0 | W23: =SUMIFS($G:$G,$H:$H,$P23,$F:$F,TEXT(W$5,"00") & "." & TEXT($A$1,"00")) -> 0 | X23: =SUMIFS($G:$G,$H:$H,$P23,$F:$F,TEXT(X$5,"00") & "." & TEXT($A$1,"00")) -> 0 | Y23: =SUMIFS($G:$G,$H:$H,$P23,$F:$F,TEXT(Y$5,"00") & "." & TEXT($A$1,"00")) -> 0 | ... AV23: =SUMIFS($G:$G,$H:$H,$P23,$F:$F,TEXT(AV$5,"00") & "." & TEXT($A$1,"00")) -> 0 | AW23: =SUM(Q23:AV23) -> 616.79
A24: סה"כ | C24: 31553.26 | D24: 42731 | G24: 53.91 | H24: ביטוח בריאות פרטי | I24: =_xlfn.XLOOKUP(H24,[2]Dropdown!B:B,[2]Dropdown!C:C) -> בריאות וטיפולים | J24: ל-ו 2 | M24: הראל | P24: גז/נפט | Q24: =SUMIFS($G:$G,$H:$H,$P24,$F:$F,"") -> 0 | R24: =SUMIFS($G:$G,$H:$H,$P24,$F:$F,TEXT(R$5,"00") & "." & TEXT($A$1,"00")) -> 0 | S24: =SUMIFS($G:$G,$H:$H,$P24,$F:$F,TEXT(S$5,"00") & "." & TEXT($A$1,"00")) -> 0 | T24: =SUMIFS($G:$G,$H:$H,$P24,$F:$F,TEXT(T$5,"00") & "." & TEXT($A$1,"00")) -> 0 | U24: =SUMIFS($G:$G,$H:$H,$P24,$F:$F,TEXT(U$5,"00") & "." & TEXT($A$1,"00")) -> 0 | V24: =SUMIFS($G:$G,$H:$H,$P24,$F:$F,TEXT(V$5,"00") & "." & TEXT($A$1,"00")) -> 0 | W24: =SUMIFS($G:$G,$H:$H,$P24,$F:$F,TEXT(W$5,"00") & "." & TEXT($A$1,"00")) -> 0 | X24: =SUMIFS($G:$G,$H:$H,$P24,$F:$F,TEXT(X$5,"00") & "." & TEXT($A$1,"00")) -> 0 | Y24: =SUMIFS($G:$G,$H:$H,$P24,$F:$F,TEXT(Y$5,"00") & "." & TEXT($A$1,"00")) -> 0 | ... AV24: =SUMIFS($G:$G,$H:$H,$P24,$F:$F,TEXT(AV$5,"00") & "." & TEXT($A$1,"00")) -> 0 | AW24: =SUM(Q24:AV24) -> 0
A25: אחרות | B25: אחרות | D25: 2280 | G25: 279.37 | H25: ביטוח בריאות פרטי | I25: =_xlfn.XLOOKUP(H25,[2]Dropdown!B:B,[2]Dropdown!C:C) -> בריאות וטיפולים | J25: ל-ו 2 | M25: הראל | P25: טלפון (נייח) | Q25: =SUMIFS($G:$G,$H:$H,$P25,$F:$F,"") -> 0 | R25: =SUMIFS($G:$G,$H:$H,$P25,$F:$F,TEXT(R$5,"00") & "." & TEXT($A$1,"00")) -> 0 | S25: =SUMIFS($G:$G,$H:$H,$P25,$F:$F,TEXT(S$5,"00") & "." & TEXT($A$1,"00")) -> 0 | T25: =SUMIFS($G:$G,$H:$H,$P25,$F:$F,TEXT(T$5,"00") & "." & TEXT($A$1,"00")) -> 0 | U25: =SUMIFS($G:$G,$H:$H,$P25,$F:$F,TEXT(U$5,"00") & "." & TEXT($A$1,"00")) -> 0 | V25: =SUMIFS($G:$G,$H:$H,$P25,$F:$F,TEXT(V$5,"00") & "." & TEXT($A$1,"00")) -> 0 | W25: =SUMIFS($G:$G,$H:$H,$P25,$F:$F,TEXT(W$5,"00") & "." & TEXT($A$1,"00")) -> 0 | X25: =SUMIFS($G:$G,$H:$H,$P25,$F:$F,TEXT(X$5,"00") & "." & TEXT($A$1,"00")) -> 0 | Y25: =SUMIFS($G:$G,$H:$H,$P25,$F:$F,TEXT(Y$5,"00") & "." & TEXT($A$1,"00")) -> 0 | ... AV25: =SUMIFS($G:$G,$H:$H,$P25,$F:$F,TEXT(AV$5,"00") & "." & TEXT($A$1,"00")) -> 0 | AW25: =SUM(Q25:AV25) -> 0
A26: סך הכנסות | C26: 31553.26 | D26: 45011 | G26: 276.68 | H26: קופ"ח + משלים | I26: =_xlfn.XLOOKUP(H26,[2]Dropdown!B:B,[2]Dropdown!C:C) -> בריאות וטיפולים | J26: ל-ו 2 | M26: כללית | P26: טלפונים ניידים | Q26: =SUMIFS($G:$G,$H:$H,$P26,$F:$F,"") -> 122.4 | R26: =SUMIFS($G:$G,$H:$H,$P26,$F:$F,TEXT(R$5,"00") & "." & TEXT($A$1,"00")) -> 0 | S26: =SUMIFS($G:$G,$H:$H,$P26,$F:$F,TEXT(S$5,"00") & "." & TEXT($A$1,"00")) -> 0 | T26: =SUMIFS($G:$G,$H:$H,$P26,$F:$F,TEXT(T$5,"00") & "." & TEXT($A$1,"00")) -> 0 | U26: =SUMIFS($G:$G,$H:$H,$P26,$F:$F,TEXT(U$5,"00") & "." & TEXT($A$1,"00")) -> 0 | V26: =SUMIFS($G:$G,$H:$H,$P26,$F:$F,TEXT(V$5,"00") & "." & TEXT($A$1,"00")) -> 0 | W26: =SUMIFS($G:$G,$H:$H,$P26,$F:$F,TEXT(W$5,"00") & "." & TEXT($A$1,"00")) -> 0 | X26: =SUMIFS($G:$G,$H:$H,$P26,$F:$F,TEXT(X$5,"00") & "." & TEXT($A$1,"00")) -> 0 | Y26: =SUMIFS($G:$G,$H:$H,$P26,$F:$F,TEXT(Y$5,"00") & "." & TEXT($A$1,"00")) -> 0 | ... AV26: =SUMIFS($G:$G,$H:$H,$P26,$F:$F,TEXT(AV$5,"00") & "." & TEXT($A$1,"00")) -> 0 | AW26: =SUM(Q26:AV26) -> 122.4
G27: 191.94 | H27: ביטוח בריאות פרטי | I27: =_xlfn.XLOOKUP(H27,[2]Dropdown!B:B,[2]Dropdown!C:C) -> בריאות וטיפולים | J27: י-ק 2 | P27: ביוב | Q27: =SUMIFS($G:$G,$H:$H,$P27,$F:$F,"") -> 0 | R27: =SUMIFS($G:$G,$H:$H,$P27,$F:$F,TEXT(R$5,"00") & "." & TEXT($A$1,"00")) -> 0 | S27: =SUMIFS($G:$G,$H:$H,$P27,$F:$F,TEXT(S$5,"00") & "." & TEXT($A$1,"00")) -> 0 | T27: =SUMIFS($G:$G,$H:$H,$P27,$F:$F,TEXT(T$5,"00") & "." & TEXT($A$1,"00")) -> 0 | U27: =SUMIFS($G:$G,$H:$H,$P27,$F:$F,TEXT(U$5,"00") & "." & TEXT($A$1,"00")) -> 0 | V27: =SUMIFS($G:$G,$H:$H,$P27,$F:$F,TEXT(V$5,"00") & "." & TEXT($A$1,"00")) -> 0 | W27: =SUMIFS($G:$G,$H:$H,$P27,$F:$F,TEXT(W$5,"00") & "." & TEXT($A$1,"00")) -> 0 | X27: =SUMIFS($G:$G,$H:$H,$P27,$F:$F,TEXT(X$5,"00") & "." & TEXT($A$1,"00")) -> 0 | Y27: =SUMIFS($G:$G,$H:$H,$P27,$F:$F,TEXT(Y$5,"00") & "." & TEXT($A$1,"00")) -> 0 | ... AV27: =SUMIFS($G:$G,$H:$H,$P27,$F:$F,TEXT(AV$5,"00") & "." & TEXT($A$1,"00")) -> 0 | AW27: =SUM(Q27:AV27) -> 0
A28: מצב חשבון | B28: יתרה חודש קודם | C28: -32401.73 | D28: 154.26 | G28: 274.9 | H28: ביטוחי חיים (ריסק) | I28: =_xlfn.XLOOKUP(H28,[2]Dropdown!B:B,[2]Dropdown!C:C) -> ביטוחים ופיננסים | J28: י-ק 2 | P28: כבלים | Q28: =SUMIFS($G:$G,$H:$H,$P28,$F:$F,"") -> 167.87 | R28: =SUMIFS($G:$G,$H:$H,$P28,$F:$F,TEXT(R$5,"00") & "." & TEXT($A$1,"00")) -> 0 | S28: =SUMIFS($G:$G,$H:$H,$P28,$F:$F,TEXT(S$5,"00") & "." & TEXT($A$1,"00")) -> 0 | T28: =SUMIFS($G:$G,$H:$H,$P28,$F:$F,TEXT(T$5,"00") & "." & TEXT($A$1,"00")) -> 0 | U28: =SUMIFS($G:$G,$H:$H,$P28,$F:$F,TEXT(U$5,"00") & "." & TEXT($A$1,"00")) -> 0 | V28: =SUMIFS($G:$G,$H:$H,$P28,$F:$F,TEXT(V$5,"00") & "." & TEXT($A$1,"00")) -> 0 | W28: =SUMIFS($G:$G,$H:$H,$P28,$F:$F,TEXT(W$5,"00") & "." & TEXT($A$1,"00")) -> 0 | X28: =SUMIFS($G:$G,$H:$H,$P28,$F:$F,TEXT(X$5,"00") & "." & TEXT($A$1,"00")) -> 0 | Y28: =SUMIFS($G:$G,$H:$H,$P28,$F:$F,TEXT(Y$5,"00") & "." & TEXT($A$1,"00")) -> 0 | ... AV28: =SUMIFS($G:$G,$H:$H,$P28,$F:$F,TEXT(AV$5,"00") & "." & TEXT($A$1,"00")) -> 0 | AW28: =SUM(Q28:AV28) -> 167.87
B29: מצב עדכני | C29: -34248.61 | D29: 6283.91 | G29: 521.98 | H29: ביטוחי חיים (ריסק) | I29: =_xlfn.XLOOKUP(H29,[2]Dropdown!B:B,[2]Dropdown!C:C) -> ביטוחים ופיננסים | J29: ל-ו 2 | M29: הראל | P29: אינטרנט | Q29: =SUMIFS($G:$G,$H:$H,$P29,$F:$F,"") -> 95 | R29: =SUMIFS($G:$G,$H:$H,$P29,$F:$F,TEXT(R$5,"00") & "." & TEXT($A$1,"00")) -> 0 | S29: =SUMIFS($G:$G,$H:$H,$P29,$F:$F,TEXT(S$5,"00") & "." & TEXT($A$1,"00")) -> 0 | T29: =SUMIFS($G:$G,$H:$H,$P29,$F:$F,TEXT(T$5,"00") & "." & TEXT($A$1,"00")) -> 0 | U29: =SUMIFS($G:$G,$H:$H,$P29,$F:$F,TEXT(U$5,"00") & "." & TEXT($A$1,"00")) -> 0 | V29: =SUMIFS($G:$G,$H:$H,$P29,$F:$F,TEXT(V$5,"00") & "." & TEXT($A$1,"00")) -> 0 | W29: =SUMIFS($G:$G,$H:$H,$P29,$F:$F,TEXT(W$5,"00") & "." & TEXT($A$1,"00")) -> 0 | X29: =SUMIFS($G:$G,$H:$H,$P29,$F:$F,TEXT(X$5,"00") & "." & TEXT($A$1,"00")) -> 0 | Y29: =SUMIFS($G:$G,$H:$H,$P29,$F:$F,TEXT(Y$5,"00") & "." & TEXT($A$1,"00")) -> 0 | ... AV29: =SUMIFS($G:$G,$H:$H,$P29,$F:$F,TEXT(AV$5,"00") & "." & TEXT($A$1,"00")) -> 0 | AW29: =SUM(Q29:AV29) -> 95
A30: אשראי | B30: יתרת אשראי | C30: 751.39 | D30: 16283.91 | G30: 71.55 | H30: ביטוחי חיים (ריסק) | I30: =_xlfn.XLOOKUP(H30,[2]Dropdown!B:B,[2]Dropdown!C:C) -> ביטוחים ופיננסים | J30: ל-ו 2 | M30: הראל | P30: ועד בית/ישוב | Q30: =SUMIFS($G:$G,$H:$H,$P30,$F:$F,"") -> 1760.4 | R30: =SUMIFS($G:$G,$H:$H,$P30,$F:$F,TEXT(R$5,"00") & "." & TEXT($A$1,"00")) -> 0 | S30: =SUMIFS($G:$G,$H:$H,$P30,$F:$F,TEXT(S$5,"00") & "." & TEXT($A$1,"00")) -> 0 | T30: =SUMIFS($G:$G,$H:$H,$P30,$F:$F,TEXT(T$5,"00") & "." & TEXT($A$1,"00")) -> 0 | U30: =SUMIFS($G:$G,$H:$H,$P30,$F:$F,TEXT(U$5,"00") & "." & TEXT($A$1,"00")) -> 0 | V30: =SUMIFS($G:$G,$H:$H,$P30,$F:$F,TEXT(V$5,"00") & "." & TEXT($A$1,"00")) -> 0 | W30: =SUMIFS($G:$G,$H:$H,$P30,$F:$F,TEXT(W$5,"00") & "." & TEXT($A$1,"00")) -> 0 | X30: =SUMIFS($G:$G,$H:$H,$P30,$F:$F,TEXT(X$5,"00") & "." & TEXT($A$1,"00")) -> 0 | Y30: =SUMIFS($G:$G,$H:$H,$P30,$F:$F,TEXT(Y$5,"00") & "." & TEXT($A$1,"00")) -> 0 | ... AV30: =SUMIFS($G:$G,$H:$H,$P30,$F:$F,TEXT(AV$5,"00") & "." & TEXT($A$1,"00")) -> 0 | AW30: =SUM(Q30:AV30) -> 1760.4
A31: יתרה | B31: רווח/הפסד | C31: -2047.18 | D31: 6129.65 | G31: 127.47 | H31: ביטוחי חיים (ריסק) | I31: =_xlfn.XLOOKUP(H31,[2]Dropdown!B:B,[2]Dropdown!C:C) -> ביטוחים ופיננסים | J31: ל-ו 2 | M31: הראל | P31: עוזרת בית | Q31: =SUMIFS($G:$G,$H:$H,$P31,$F:$F,"") -> 454.3 | R31: =SUMIFS($G:$G,$H:$H,$P31,$F:$F,TEXT(R$5,"00") & "." & TEXT($A$1,"00")) -> 0 | S31: =SUMIFS($G:$G,$H:$H,$P31,$F:$F,TEXT(S$5,"00") & "." & TEXT($A$1,"00")) -> 0 | T31: =SUMIFS($G:$G,$H:$H,$P31,$F:$F,TEXT(T$5,"00") & "." & TEXT($A$1,"00")) -> 0 | U31: =SUMIFS($G:$G,$H:$H,$P31,$F:$F,TEXT(U$5,"00") & "." & TEXT($A$1,"00")) -> 0 | V31: =SUMIFS($G:$G,$H:$H,$P31,$F:$F,TEXT(V$5,"00") & "." & TEXT($A$1,"00")) -> 0 | W31: =SUMIFS($G:$G,$H:$H,$P31,$F:$F,TEXT(W$5,"00") & "." & TEXT($A$1,"00")) -> 0 | X31: =SUMIFS($G:$G,$H:$H,$P31,$F:$F,TEXT(X$5,"00") & "." & TEXT($A$1,"00")) -> 0 | Y31: =SUMIFS($G:$G,$H:$H,$P31,$F:$F,TEXT(Y$5,"00") & "." & TEXT($A$1,"00")) -> 0 | ... AV31: =SUMIFS($G:$G,$H:$H,$P31,$F:$F,TEXT(AV$5,"00") & "." & TEXT($A$1,"00")) -> 0 | AW31: =SUM(Q31:AV31) -> 454.3
B32: יתרה חודשית | C32: -1846.88 | D32: 6129.65 | G32: 98.53 | H32: ביטוחי חיים (ריסק) | I32: =_xlfn.XLOOKUP(H32,[2]Dropdown!B:B,[2]Dropdown!C:C) -> ביטוחים ופיננסים | J32: ל-ו 2 | M32: הראל | P32: גינון | Q32: =SUMIFS($G:$G,$H:$H,$P32,$F:$F,"") -> 0 | R32: =SUMIFS($G:$G,$H:$H,$P32,$F:$F,TEXT(R$5,"00") & "." & TEXT($A$1,"00")) -> 0 | S32: =SUMIFS($G:$G,$H:$H,$P32,$F:$F,TEXT(S$5,"00") & "." & TEXT($A$1,"00")) -> 0 | T32: =SUMIFS($G:$G,$H:$H,$P32,$F:$F,TEXT(T$5,"00") & "." & TEXT($A$1,"00")) -> 0 | U32: =SUMIFS($G:$G,$H:$H,$P32,$F:$F,TEXT(U$5,"00") & "." & TEXT($A$1,"00")) -> 0 | V32: =SUMIFS($G:$G,$H:$H,$P32,$F:$F,TEXT(V$5,"00") & "." & TEXT($A$1,"00")) -> 0 | W32: =SUMIFS($G:$G,$H:$H,$P32,$F:$F,TEXT(W$5,"00") & "." & TEXT($A$1,"00")) -> 0 | X32: =SUMIFS($G:$G,$H:$H,$P32,$F:$F,TEXT(X$5,"00") & "." & TEXT($A$1,"00")) -> 0 | Y32: =SUMIFS($G:$G,$H:$H,$P32,$F:$F,TEXT(Y$5,"00") & "." & TEXT($A$1,"00")) -> 0 | ... AV32: =SUMIFS($G:$G,$H:$H,$P32,$F:$F,TEXT(AV$5,"00") & "." & TEXT($A$1,"00")) -> 0 | AW32: =SUM(Q32:AV32) -> 0
G33: 4000 | H33: תוכניות חסכון | I33: =_xlfn.XLOOKUP(H33,[2]Dropdown!B:B,[2]Dropdown!C:C) -> ביטוחים ופיננסים | J33: חש-ד | P33: ביטוח דירה | Q33: =SUMIFS($G:$G,$H:$H,$P33,$F:$F,"") -> 100 | R33: =SUMIFS($G:$G,$H:$H,$P33,$F:$F,TEXT(R$5,"00") & "." & TEXT($A$1,"00")) -> 0 | S33: =SUMIFS($G:$G,$H:$H,$P33,$F:$F,TEXT(S$5,"00") & "." & TEXT($A$1,"00")) -> 0 | T33: =SUMIFS($G:$G,$H:$H,$P33,$F:$F,TEXT(T$5,"00") & "." & TEXT($A$1,"00")) -> 0 | U33: =SUMIFS($G:$G,$H:$H,$P33,$F:$F,TEXT(U$5,"00") & "." & TEXT($A$1,"00")) -> 0 | V33: =SUMIFS($G:$G,$H:$H,$P33,$F:$F,TEXT(V$5,"00") & "." & TEXT($A$1,"00")) -> 0 | W33: =SUMIFS($G:$G,$H:$H,$P33,$F:$F,TEXT(W$5,"00") & "." & TEXT($A$1,"00")) -> 0 | X33: =SUMIFS($G:$G,$H:$H,$P33,$F:$F,TEXT(X$5,"00") & "." & TEXT($A$1,"00")) -> 0 | Y33: =SUMIFS($G:$G,$H:$H,$P33,$F:$F,TEXT(Y$5,"00") & "." & TEXT($A$1,"00")) -> 0 | ... AV33: =SUMIFS($G:$G,$H:$H,$P33,$F:$F,TEXT(AV$5,"00") & "." & TEXT($A$1,"00")) -> 0 | AW33: =SUM(Q33:AV33) -> 100
C34: החזר חודשי | D34: יתרה | G34: =454.3 -> 454.3 | H34: עוזרת בית | I34: =_xlfn.XLOOKUP(H34,[2]Dropdown!B:B,[2]Dropdown!C:C) -> תחזוקת דירה ותקשורת | J34: חש-ד | P34: רכישות לבית | Q34: =SUMIFS($G:$G,$H:$H,$P34,$F:$F,"") -> 0 | R34: =SUMIFS($G:$G,$H:$H,$P34,$F:$F,TEXT(R$5,"00") & "." & TEXT($A$1,"00")) -> 0 | S34: =SUMIFS($G:$G,$H:$H,$P34,$F:$F,TEXT(S$5,"00") & "." & TEXT($A$1,"00")) -> 0 | T34: =SUMIFS($G:$G,$H:$H,$P34,$F:$F,TEXT(T$5,"00") & "." & TEXT($A$1,"00")) -> 0 | U34: =SUMIFS($G:$G,$H:$H,$P34,$F:$F,TEXT(U$5,"00") & "." & TEXT($A$1,"00")) -> 0 | V34: =SUMIFS($G:$G,$H:$H,$P34,$F:$F,TEXT(V$5,"00") & "." & TEXT($A$1,"00")) -> 0 | W34: =SUMIFS($G:$G,$H:$H,$P34,$F:$F,TEXT(W$5,"00") & "." & TEXT($A$1,"00")) -> 0 | X34: =SUMIFS($G:$G,$H:$H,$P34,$F:$F,TEXT(X$5,"00") & "." & TEXT($A$1,"00")) -> 0 | Y34: =SUMIFS($G:$G,$H:$H,$P34,$F:$F,TEXT(Y$5,"00") & "." & TEXT($A$1,"00")) -> 0 | ... AV34: =SUMIFS($G:$G,$H:$H,$P34,$F:$F,TEXT(AV$5,"00") & "." & TEXT($A$1,"00")) -> 0 | AW34: =SUM(Q34:AV34) -> 0
A35: הלוואות | B35: אדי ויידה | D35: 58550 | G35: =12000+2000 -> 14000 | H35: משכורת | I35: =_xlfn.XLOOKUP(H35,[2]Dropdown!B:B,[2]Dropdown!C:C) -> עסק | J35: חש-ל | P35: אחזקת בית ותיקונים | Q35: =SUMIFS($G:$G,$H:$H,$P35,$F:$F,"") -> 0 | R35: =SUMIFS($G:$G,$H:$H,$P35,$F:$F,TEXT(R$5,"00") & "." & TEXT($A$1,"00")) -> 0 | S35: =SUMIFS($G:$G,$H:$H,$P35,$F:$F,TEXT(S$5,"00") & "." & TEXT($A$1,"00")) -> 0 | T35: =SUMIFS($G:$G,$H:$H,$P35,$F:$F,TEXT(T$5,"00") & "." & TEXT($A$1,"00")) -> 0 | U35: =SUMIFS($G:$G,$H:$H,$P35,$F:$F,TEXT(U$5,"00") & "." & TEXT($A$1,"00")) -> 0 | V35: =SUMIFS($G:$G,$H:$H,$P35,$F:$F,TEXT(V$5,"00") & "." & TEXT($A$1,"00")) -> 0 | W35: =SUMIFS($G:$G,$H:$H,$P35,$F:$F,TEXT(W$5,"00") & "." & TEXT($A$1,"00")) -> 0 | X35: =SUMIFS($G:$G,$H:$H,$P35,$F:$F,TEXT(X$5,"00") & "." & TEXT($A$1,"00")) -> 0 | Y35: =SUMIFS($G:$G,$H:$H,$P35,$F:$F,TEXT(Y$5,"00") & "." & TEXT($A$1,"00")) -> 0 | ... AV35: =SUMIFS($G:$G,$H:$H,$P35,$F:$F,TEXT(AV$5,"00") & "." & TEXT($A$1,"00")) -> 0 | AW35: =SUM(Q35:AV35) -> 0
B36: סבא | D36: 136176 | G36: 3217.61 | H36: פנסיה | I36: =_xlfn.XLOOKUP(H36,[2]Dropdown!B:B,[2]Dropdown!C:C) -> עסק | J36: חש-ל | P36: מנויים דיגטליים | Q36: =SUMIFS($G:$G,$H:$H,$P36,$F:$F,"") -> 0 | R36: =SUMIFS($G:$G,$H:$H,$P36,$F:$F,TEXT(R$5,"00") & "." & TEXT($A$1,"00")) -> 0 | S36: =SUMIFS($G:$G,$H:$H,$P36,$F:$F,TEXT(S$5,"00") & "." & TEXT($A$1,"00")) -> 0 | T36: =SUMIFS($G:$G,$H:$H,$P36,$F:$F,TEXT(T$5,"00") & "." & TEXT($A$1,"00")) -> 0 | U36: =SUMIFS($G:$G,$H:$H,$P36,$F:$F,TEXT(U$5,"00") & "." & TEXT($A$1,"00")) -> 0 | V36: =SUMIFS($G:$G,$H:$H,$P36,$F:$F,TEXT(V$5,"00") & "." & TEXT($A$1,"00")) -> 0 | W36: =SUMIFS($G:$G,$H:$H,$P36,$F:$F,TEXT(W$5,"00") & "." & TEXT($A$1,"00")) -> 0 | X36: =SUMIFS($G:$G,$H:$H,$P36,$F:$F,TEXT(X$5,"00") & "." & TEXT($A$1,"00")) -> 0 | Y36: =SUMIFS($G:$G,$H:$H,$P36,$F:$F,TEXT(Y$5,"00") & "." & TEXT($A$1,"00")) -> 0 | ... AV36: =SUMIFS($G:$G,$H:$H,$P36,$F:$F,TEXT(AV$5,"00") & "." & TEXT($A$1,"00")) -> 0 | AW36: =SUM(Q36:AV36) -> 0
G37: 11306 | H37: מע"מ | I37: =_xlfn.XLOOKUP(H37,[2]Dropdown!B:B,[2]Dropdown!C:C) -> עסק | J37: ל-פ 2 | P37: בנייה | Q37: =SUMIFS($G:$G,$H:$H,$P37,$F:$F,"") -> 2360 | R37: =SUMIFS($G:$G,$H:$H,$P37,$F:$F,TEXT(R$5,"00") & "." & TEXT($A$1,"00")) -> 0 | S37: =SUMIFS($G:$G,$H:$H,$P37,$F:$F,TEXT(S$5,"00") & "." & TEXT($A$1,"00")) -> 0 | T37: =SUMIFS($G:$G,$H:$H,$P37,$F:$F,TEXT(T$5,"00") & "." & TEXT($A$1,"00")) -> 0 | U37: =SUMIFS($G:$G,$H:$H,$P37,$F:$F,TEXT(U$5,"00") & "." & TEXT($A$1,"00")) -> 0 | V37: =SUMIFS($G:$G,$H:$H,$P37,$F:$F,TEXT(V$5,"00") & "." & TEXT($A$1,"00")) -> 0 | W37: =SUMIFS($G:$G,$H:$H,$P37,$F:$F,TEXT(W$5,"00") & "." & TEXT($A$1,"00")) -> 0 | X37: =SUMIFS($G:$G,$H:$H,$P37,$F:$F,TEXT(X$5,"00") & "." & TEXT($A$1,"00")) -> 0 | Y37: =SUMIFS($G:$G,$H:$H,$P37,$F:$F,TEXT(Y$5,"00") & "." & TEXT($A$1,"00")) -> 0 | ... AV37: =SUMIFS($G:$G,$H:$H,$P37,$F:$F,TEXT(AV$5,"00") & "." & TEXT($A$1,"00")) -> 0 | AW37: =SUM(Q37:AV37) -> 2360
G38: 5534 | H38: מס הכנסה | I38: =_xlfn.XLOOKUP(H38,[2]Dropdown!B:B,[2]Dropdown!C:C) -> עסק | J38: ל-פ 2
C39: 0 | D39: 194726 | G39: 4794 | H39: ביטוח לאומי | I39: =_xlfn.XLOOKUP(H39,[2]Dropdown!B:B,[2]Dropdown!C:C) -> עסק | J39: ל-פ 2
G40: 600 | H40: רו"ח | I40: =_xlfn.XLOOKUP(H40,[2]Dropdown!B:B,[2]Dropdown!C:C) -> עסק | J40: חש-ל
...

Sheet 1225
A1: 12 | B1: 11 | C1: דיסקונט | D1: לאומי | F1: תאריך | G1: סכום | H1: סוג הוצאה | I1: קטגוריה | J1: איך | K1: # | L1: סיום | N1: בלת"ם
A2: כרטיסי אשראי | B2: כ"א לאומי לילי | C2: 20378.03 | D2: 0 | F2: קבועות
B3: כ"א לאומי לילי חו"ל | C3: 1907 | G3: 10 | H3: עמלות | I3: =_xlfn.XLOOKUP(H3,[2]Dropdown!B:B,[2]Dropdown!C:C) -> ביטוחים ופיננסים | J3: חש-ל
B4: כ"א קאל יניב | C4: 4526.31 | D4: 28780.35 | G4: 371.4 | H4: ביוב | I4: =_xlfn.XLOOKUP(H4,[2]Dropdown!B:B,[2]Dropdown!C:C) -> תחזוקת דירה ותקשורת | J4: ל-ו 2
G5: 703.8 | H5: ארנונה | I5: =_xlfn.XLOOKUP(H5,[2]Dropdown!B:B,[2]Dropdown!C:C) -> תחזוקת דירה ותקשורת | J5: ל-ו 2 | Q5: קבוע | R5: 1 | S5: 2 | T5: 3 | U5: 4 | V5: 5 | W5: 6 | X5: 7 | Y5: 8 | Z5: 9 | AA5: 10 | AB5: 11 | AC5: 12 | AD5: 13 | AE5: 14 | AF5: 15 | AG5: 16 | AH5: 17 | AI5: 18 | AJ5: 19 | AK5: 20 | AL5: 21 | AM5: 22 | AN5: 23 | AO5: 24 | AP5: 25 | AQ5: 26 | AR5: 27 | AS5: 28 | AT5: 29 | AU5: 30 | AV5: 31 | AW5: סה"כ
G6: 1760.4 | H6: ועד בית/ישוב | I6: =_xlfn.XLOOKUP(H6,[2]Dropdown!B:B,[2]Dropdown!C:C) -> תחזוקת דירה ותקשורת | J6: העברה | P6: תחזוקת דירה ותקשורת | Q6: =SUMIFS($G:$G,$I:$I,$P6,$F:$F,"") -> 16265.52 | R6: =SUMIFS($G:$G,$I:$I,$P6,$F:$F, TEXT(R$5,"00") & "." & TEXT($A$1,"00")) -> 0 | S6: =SUMIFS($G:$G,$I:$I,$P6,$F:$F, TEXT(S$5,"00") & "." & TEXT($A$1,"00")) -> 0 | T6: =SUMIFS($G:$G,$I:$I,$P6,$F:$F, TEXT(T$5,"00") & "." & TEXT($A$1,"00")) -> 0 | U6: =SUMIFS($G:$G,$I:$I,$P6,$F:$F, TEXT(U$5,"00") & "." & TEXT($A$1,"00")) -> 405 | V6: =SUMIFS($G:$G,$I:$I,$P6,$F:$F, TEXT(V$5,"00") & "." & TEXT($A$1,"00")) -> 0 | W6: =SUMIFS($G:$G,$I:$I,$P6,$F:$F, TEXT(W$5,"00") & "." & TEXT($A$1,"00")) -> 0 | X6: =SUMIFS($G:$G,$I:$I,$P6,$F:$F, TEXT(X$5,"00") & "." & TEXT($A$1,"00")) -> 0 | Y6: =SUMIFS($G:$G,$I:$I,$P6,$F:$F, TEXT(Y$5,"00") & "." & TEXT($A$1,"00")) -> 0 | ... AV6: =SUMIFS($G:$G,$I:$I,$P6,$F:$F, TEXT(AV$5,"00") & "." & TEXT($A$1,"00")) -> 32175.76 | AW6: =SUM(Q6:AV6) -> 226896.28
A7: הלוואה | B7: הלוואה | C7: 0 | D7: 0 | G7: 0 | H7: טלפון (נייח) | I7: =_xlfn.XLOOKUP(H7,[2]Dropdown!B:B,[2]Dropdown!C:C) -> תחזוקת דירה ותקשורת | J7: העברה | P7: מזון וקניות | Q7: =SUMIFS($G:$G,$I:$I,$P7,$F:$F,"") -> 2673.77 | R7: =SUMIFS($G:$G,$I:$I,$P7,$F:$F, TEXT(R$5,"00") & "." & TEXT($A$1,"00")) -> 0 | S7: =SUMIFS($G:$G,$I:$I,$P7,$F:$F, TEXT(S$5,"00") & "." & TEXT($A$1,"00")) -> 750.66 | T7: =SUMIFS($G:$G,$I:$I,$P7,$F:$F, TEXT(T$5,"00") & "." & TEXT($A$1,"00")) -> -79.12 | U7: =SUMIFS($G:$G,$I:$I,$P7,$F:$F, TEXT(U$5,"00") & "." & TEXT($A$1,"00")) -> 148 | V7: =SUMIFS($G:$G,$I:$I,$P7,$F:$F, TEXT(V$5,"00") & "." & TEXT($A$1,"00")) -> 735.53 | W7: =SUMIFS($G:$G,$I:$I,$P7,$F:$F, TEXT(W$5,"00") & "." & TEXT($A$1,"00")) -> 0 | X7: =SUMIFS($G:$G,$I:$I,$P7,$F:$F, TEXT(X$5,"00") & "." & TEXT($A$1,"00")) -> 0 | Y7: =SUMIFS($G:$G,$I:$I,$P7,$F:$F, TEXT(Y$5,"00") & "." & TEXT($A$1,"00")) -> 867.68 | ... AV7: =SUMIFS($G:$G,$I:$I,$P7,$F:$F, TEXT(AV$5,"00") & "." & TEXT($A$1,"00")) -> 372.59 | AW7: =SUM(Q7:AV7) -> 12495.93
B8: משכנתא | C8: 4532.74 | G8: 95 | H8: אינטרנט | I8: =_xlfn.XLOOKUP(H8,[2]Dropdown!B:B,[2]Dropdown!C:C) -> תחזוקת דירה ותקשורת | J8: העברה | P8: רכב ונסיעות | Q8: =SUMIFS($G:$G,$I:$I,$P8,$F:$F,"") -> 587 | R8: =SUMIFS($G:$G,$I:$I,$P8,$F:$F, TEXT(R$5,"00") & "." & TEXT($A$1,"00")) -> 0 | S8: =SUMIFS($G:$G,$I:$I,$P8,$F:$F, TEXT(S$5,"00") & "." & TEXT($A$1,"00")) -> 244.99 | T8: =SUMIFS($G:$G,$I:$I,$P8,$F:$F, TEXT(T$5,"00") & "." & TEXT($A$1,"00")) -> 0 | U8: =SUMIFS($G:$G,$I:$I,$P8,$F:$F, TEXT(U$5,"00") & "." & TEXT($A$1,"00")) -> 48.8 | V8: =SUMIFS($G:$G,$I:$I,$P8,$F:$F, TEXT(V$5,"00") & "." & TEXT($A$1,"00")) -> 0 | W8: =SUMIFS($G:$G,$I:$I,$P8,$F:$F, TEXT(W$5,"00") & "." & TEXT($A$1,"00")) -> 0 | X8: =SUMIFS($G:$G,$I:$I,$P8,$F:$F, TEXT(X$5,"00") & "." & TEXT($A$1,"00")) -> 568.63 | Y8: =SUMIFS($G:$G,$I:$I,$P8,$F:$F, TEXT(Y$5,"00") & "." & TEXT($A$1,"00")) -> 0 | ... AV8: =SUMIFS($G:$G,$I:$I,$P8,$F:$F, TEXT(AV$5,"00") & "." & TEXT($A$1,"00")) -> 0 | AW8: =SUM(Q8:AV8) -> 4544.9
A9: קבועים | B9: קיבוץ/שוטף | C9: 2934.4 | D9: 6727.61 | G9: 112 | H9: קופ"ח + משלים | I9: =_xlfn.XLOOKUP(H9,[2]Dropdown!B:B,[2]Dropdown!C:C) -> בריאות וטיפולים | J9: העברה | P9: ילדים וחינוך | Q9: =SUMIFS($G:$G,$I:$I,$P9,$F:$F,"") -> 4311.72 | R9: =SUMIFS($G:$G,$I:$I,$P9,$F:$F, TEXT(R$5,"00") & "." & TEXT($A$1,"00")) -> 0 | S9: =SUMIFS($G:$G,$I:$I,$P9,$F:$F, TEXT(S$5,"00") & "." & TEXT($A$1,"00")) -> 0 | T9: =SUMIFS($G:$G,$I:$I,$P9,$F:$F, TEXT(T$5,"00") & "." & TEXT($A$1,"00")) -> 0 | U9: =SUMIFS($G:$G,$I:$I,$P9,$F:$F, TEXT(U$5,"00") & "." & TEXT($A$1,"00")) -> 0 | V9: =SUMIFS($G:$G,$I:$I,$P9,$F:$F, TEXT(V$5,"00") & "." & TEXT($A$1,"00")) -> 0 | W9: =SUMIFS($G:$G,$I:$I,$P9,$F:$F, TEXT(W$5,"00") & "." & TEXT($A$1,"00")) -> 150 | X9: =SUMIFS($G:$G,$I:$I,$P9,$F:$F, TEXT(X$5,"00") & "." & TEXT($A$1,"00")) -> 0 | Y9: =SUMIFS($G:$G,$I:$I,$P9,$F:$F, TEXT(Y$5,"00") & "." & TEXT($A$1,"00")) -> 0 | ... AV9: =SUMIFS($G:$G,$I:$I,$P9,$F:$F, TEXT(AV$5,"00") & "." & TEXT($A$1,"00")) -> 0 | AW9: =SUM(Q9:AV9) -> 5361.72
B10: אחר | C10: -26442.84 | G10: 389 | H10: ביטוח בריאות פרטי | I10: =_xlfn.XLOOKUP(H10,[2]Dropdown!B:B,[2]Dropdown!C:C) -> בריאות וטיפולים | J10: העברה | P10: תרבות ופנאי | Q10: =SUMIFS($G:$G,$I:$I,$P10,$F:$F,"") -> 0 | R10: =SUMIFS($G:$G,$I:$I,$P10,$F:$F, TEXT(R$5,"00") & "." & TEXT($A$1,"00")) -> 97 | S10: =SUMIFS($G:$G,$I:$I,$P10,$F:$F, TEXT(S$5,"00") & "." & TEXT($A$1,"00")) -> 135.9 | T10: =SUMIFS($G:$G,$I:$I,$P10,$F:$F, TEXT(T$5,"00") & "." & TEXT($A$1,"00")) -> 193 | U10: =SUMIFS($G:$G,$I:$I,$P10,$F:$F, TEXT(U$5,"00") & "." & TEXT($A$1,"00")) -> 0 | V10: =SUMIFS($G:$G,$I:$I,$P10,$F:$F, TEXT(V$5,"00") & "." & TEXT($A$1,"00")) -> 0 | W10: =SUMIFS($G:$G,$I:$I,$P10,$F:$F, TEXT(W$5,"00") & "." & TEXT($A$1,"00")) -> 181.58 | X10: =SUMIFS($G:$G,$I:$I,$P10,$F:$F, TEXT(X$5,"00") & "." & TEXT($A$1,"00")) -> 0 | Y10: =SUMIFS($G:$G,$I:$I,$P10,$F:$F, TEXT(Y$5,"00") & "." & TEXT($A$1,"00")) -> 19 | ... AV10: =SUMIFS($G:$G,$I:$I,$P10,$F:$F, TEXT(AV$5,"00") & "." & TEXT($A$1,"00")) -> 27 | AW10: =SUM(Q10:AV10) -> 4861.39
A11: תשלומים | B11: עמלות | C11: 1218.76 | D11: 22 | G11: 0 | H11: ביטוח דירה | I11: =_xlfn.XLOOKUP(H11,[2]Dropdown!B:B,[2]Dropdown!C:C) -> תחזוקת דירה ותקשורת | J11: העברה | P11: בריאות וטיפולים | Q11: =SUMIFS($G:$G,$I:$I,$P11,$F:$F,"") -> 1374.16 | R11: =SUMIFS($G:$G,$I:$I,$P11,$F:$F, TEXT(R$5,"00") & "." & TEXT($A$1,"00")) -> 0 | S11: =SUMIFS($G:$G,$I:$I,$P11,$F:$F, TEXT(S$5,"00") & "." & TEXT($A$1,"00")) -> 0 | T11: =SUMIFS($G:$G,$I:$I,$P11,$F:$F, TEXT(T$5,"00") & "." & TEXT($A$1,"00")) -> 0 | U11: =SUMIFS($G:$G,$I:$I,$P11,$F:$F, TEXT(U$5,"00") & "." & TEXT($A$1,"00")) -> 0 | V11: =SUMIFS($G:$G,$I:$I,$P11,$F:$F, TEXT(V$5,"00") & "." & TEXT($A$1,"00")) -> 0 | W11: =SUMIFS($G:$G,$I:$I,$P11,$F:$F, TEXT(W$5,"00") & "." & TEXT($A$1,"00")) -> 0 | X11: =SUMIFS($G:$G,$I:$I,$P11,$F:$F, TEXT(X$5,"00") & "." & TEXT($A$1,"00")) -> 0 | Y11: =SUMIFS($G:$G,$I:$I,$P11,$F:$F, TEXT(Y$5,"00") & "." & TEXT($A$1,"00")) -> 0 | ... AV11: =SUMIFS($G:$G,$I:$I,$P11,$F:$F, TEXT(AV$5,"00") & "." & TEXT($A$1,"00")) -> 0 | AW11: =SUM(Q11:AV11) -> 1424.89
B12: העברה בין חשבונות | C12: -633417.24 | D12: 15000 | G12: 647 | H12: מים | I12: =_xlfn.XLOOKUP(H12,[2]Dropdown!B:B,[2]Dropdown!C:C) -> תחזוקת דירה ותקשורת | J12: העברה | P12: ביטוחים ופיננסים | Q12: =SUMIFS($G:$G,$I:$I,$P12,$F:$F,"") -> 3026.66 | R12: =SUMIFS($G:$G,$I:$I,$P12,$F:$F, TEXT(R$5,"00") & "." & TEXT($A$1,"00")) -> 0 | S12: =SUMIFS($G:$G,$I:$I,$P12,$F:$F, TEXT(S$5,"00") & "." & TEXT($A$1,"00")) -> 778 | T12: =SUMIFS($G:$G,$I:$I,$P12,$F:$F, TEXT(T$5,"00") & "." & TEXT($A$1,"00")) -> 0 | U12: =SUMIFS($G:$G,$I:$I,$P12,$F:$F, TEXT(U$5,"00") & "." & TEXT($A$1,"00")) -> 0 | V12: =SUMIFS($G:$G,$I:$I,$P12,$F:$F, TEXT(V$5,"00") & "." & TEXT($A$1,"00")) -> 0 | W12: =SUMIFS($G:$G,$I:$I,$P12,$F:$F, TEXT(W$5,"00") & "." & TEXT($A$1,"00")) -> 0 | X12: =SUMIFS($G:$G,$I:$I,$P12,$F:$F, TEXT(X$5,"00") & "." & TEXT($A$1,"00")) -> 0 | Y12: =SUMIFS($G:$G,$I:$I,$P12,$F:$F, TEXT(Y$5,"00") & "." & TEXT($A$1,"00")) -> 0 | ... AV12: =SUMIFS($G:$G,$I:$I,$P12,$F:$F, TEXT(AV$5,"00") & "." & TEXT($A$1,"00")) -> 452.76 | AW12: =SUM(Q12:AV12) -> 4311.04
B13: העברה | G13: 205 | H13: חוגים וקייטנות | I13: =_xlfn.XLOOKUP(H13,[2]Dropdown!B:B,[2]Dropdown!C:C) -> ילדים וחינוך | J13: העברה | P13: עסק | Q13: =SUMIFS($G:$G,$I:$I,$P13,$F:$F,"") -> 33257.61 | R13: =SUMIFS($G:$G,$I:$I,$P13,$F:$F, TEXT(R$5,"00") & "." & TEXT($A$1,"00")) -> 0 | S13: =SUMIFS($G:$G,$I:$I,$P13,$F:$F, TEXT(S$5,"00") & "." & TEXT($A$1,"00")) -> 0 | T13: =SUMIFS($G:$G,$I:$I,$P13,$F:$F, TEXT(T$5,"00") & "." & TEXT($A$1,"00")) -> 0 | U13: =SUMIFS($G:$G,$I:$I,$P13,$F:$F, TEXT(U$5,"00") & "." & TEXT($A$1,"00")) -> 0 | V13: =SUMIFS($G:$G,$I:$I,$P13,$F:$F, TEXT(V$5,"00") & "." & TEXT($A$1,"00")) -> 0 | W13: =SUMIFS($G:$G,$I:$I,$P13,$F:$F, TEXT(W$5,"00") & "." & TEXT($A$1,"00")) -> 0 | X13: =SUMIFS($G:$G,$I:$I,$P13,$F:$F, TEXT(X$5,"00") & "." & TEXT($A$1,"00")) -> 0 | Y13: =SUMIFS($G:$G,$I:$I,$P13,$F:$F, TEXT(Y$5,"00") & "." & TEXT($A$1,"00")) -> 0 | ... AV13: =SUMIFS($G:$G,$I:$I,$P13,$F:$F, TEXT(AV$5,"00") & "." & TEXT($A$1,"00")) -> 0 | AW13: =SUM(Q13:AV13) -> 33257.61
A14: מזומן | B14: כספומט | C14: 300 | D14: 385 | G14: 0 | H14: חוגים וקייטנות | I14: =_xlfn.XLOOKUP(H14,[2]Dropdown!B:B,[2]Dropdown!C:C) -> ילדים וחינוך | J14: העברה
A15: שחרור פקדון | C15: -3051.03 | D15: 0 | G15: 1417.68 | H15: משכנתא | I15: =_xlfn.XLOOKUP(H15,[2]Dropdown!B:B,[2]Dropdown!C:C) -> תחזוקת דירה ותקשורת | J15: חש-ד
A16: חסכון | B16: פקדון | C16: 500 | D16: 0 | G16: 1521.12 | H16: משכנתא | I16: =_xlfn.XLOOKUP(H16,[2]Dropdown!B:B,[2]Dropdown!C:C) -> תחזוקת דירה ותקשורת | J16: חש-ד
A17: הוצאות עתידיות | G17: 1593.94 | H17: משכנתא | I17: =_xlfn.XLOOKUP(H17,[2]Dropdown!B:B,[2]Dropdown!C:C) -> תחזוקת דירה ותקשורת | J17: חש-ד | P17: קטגוריה
A18: סך הוצאות | C18: -626613.87 | D18: 50914.96 | G18: 689.66 | H18: חשמל | I18: =_xlfn.XLOOKUP(H18,[2]Dropdown!B:B,[2]Dropdown!C:C) -> תחזוקת דירה ותקשורת | J18: י-ק 2 | P18: תחזוקת דירה ותקשורת | Q18: קבוע | R18: 1 | S18: 2 | T18: 3 | U18: 4 | V18: 5 | W18: 6 | X18: 7 | Y18: 8 | Z18: 9 | AA18: 10 | AB18: 11 | AC18: 12 | AD18: 13 | AE18: 14 | AF18: 15 | AG18: 16 | AH18: 17 | AI18: 18 | AJ18: 19 | AK18: 20 | AL18: 21 | AM18: 22 | AN18: 23 | AO18: 24 | AP18: 25 | AQ18: 26 | AR18: 27 | AS18: 28 | AT18: 29 | AU18: 30 | AV18: 31 | AW18: סה"כ
G19: 99.82 | H19: כבלים | I19: =_xlfn.XLOOKUP(H19,[2]Dropdown!B:B,[2]Dropdown!C:C) -> תחזוקת דירה ותקשורת | J19: ל-ו 2 | P19: {=_xlfn._xlws.FILTER(Dropdown!$B:$B,Dropdown!$C:$C = $P$18)} -> משכנתא | Q19: =SUMIFS($G:$G,$H:$H,$P19,$F:$F,"") -> 4532.74 | R19: =SUMIFS($G:$G,$H:$H,$P19,$F:$F,TEXT(R$5,"00") & "." & TEXT($A$1,"00")) -> 0 | S19: =SUMIFS($G:$G,$H:$H,$P19,$F:$F,TEXT(S$5,"00") & "." & TEXT($A$1,"00")) -> 0 | T19: =SUMIFS($G:$G,$H:$H,$P19,$F:$F,TEXT(T$5,"00") & "." & TEXT($A$1,"00")) -> 0 | U19: =SUMIFS($G:$G,$H:$H,$P19,$F:$F,TEXT(U$5,"00") & "." & TEXT($A$1,"00")) -> 0 | V19: =SUMIFS($G:$G,$H:$H,$P19,$F:$F,TEXT(V$5,"00") & "." & TEXT($A$1,"00")) -> 0 | W19: =SUMIFS($G:$G,$H:$H,$P19,$F:$F,TEXT(W$5,"00") & "." & TEXT($A$1,"00")) -> 0 | X19: =SUMIFS($G:$G,$H:$H,$P19,$F:$F,TEXT(X$5,"00") & "." & TEXT($A$1,"00")) -> 0 | Y19: =SUMIFS($G:$G,$H:$H,$P19,$F:$F,TEXT(Y$5,"00") & "." & TEXT($A$1,"00")) -> 0 | ... AV19: =SUMIFS($G:$G,$H:$H,$P19,$F:$F,TEXT(AV$5,"00") & "." & TEXT($A$1,"00")) -> 0 | AW19: =SUM(Q19:AV19) -> 4532.74
A20: הכנסות | B20: משכורת יניב | C20: 15134.42 | D20: 0 | G20: 69.9 | H20: כבלים | I20: =_xlfn.XLOOKUP(H20,[2]Dropdown!B:B,[2]Dropdown!C:C) -> תחזוקת דירה ותקשורת | J20: ל-ח 1 | P20: שכר דירה | Q20: =SUMIFS($G:$G,$H:$H,$P20,$F:$F,"") -> 0 | R20: =SUMIFS($G:$G,$H:$H,$P20,$F:$F,TEXT(R$5,"00") & "." & TEXT($A$1,"00")) -> 0 | S20: =SUMIFS($G:$G,$H:$H,$P20,$F:$F,TEXT(S$5,"00") & "." & TEXT($A$1,"00")) -> 0 | T20: =SUMIFS($G:$G,$H:$H,$P20,$F:$F,TEXT(T$5,"00") & "." & TEXT($A$1,"00")) -> 0 | U20: =SUMIFS($G:$G,$H:$H,$P20,$F:$F,TEXT(U$5,"00") & "." & TEXT($A$1,"00")) -> 0 | V20: =SUMIFS($G:$G,$H:$H,$P20,$F:$F,TEXT(V$5,"00") & "." & TEXT($A$1,"00")) -> 0 | W20: =SUMIFS($G:$G,$H:$H,$P20,$F:$F,TEXT(W$5,"00") & "." & TEXT($A$1,"00")) -> 0 | X20: =SUMIFS($G:$G,$H:$H,$P20,$F:$F,TEXT(X$5,"00") & "." & TEXT($A$1,"00")) -> 0 | Y20: =SUMIFS($G:$G,$H:$H,$P20,$F:$F,TEXT(Y$5,"00") & "." & TEXT($A$1,"00")) -> 0 | ... AV20: =SUMIFS($G:$G,$H:$H,$P20,$F:$F,TEXT(AV$5,"00") & "." & TEXT($A$1,"00")) -> 0 | AW20: =SUM(Q20:AV20) -> 0
B21: משכורת לילי | C21: 15000 | D21: 50708 | G21: 44.9 | H21: כבלים | I21: =_xlfn.XLOOKUP(H21,[2]Dropdown!B:B,[2]Dropdown!C:C) -> תחזוקת דירה ותקשורת | J21: ל-ח 1 | P21: ארנונה | Q21: =SUMIFS($G:$G,$H:$H,$P21,$F:$F,"") -> 703.8 | R21: =SUMIFS($G:$G,$H:$H,$P21,$F:$F,TEXT(R$5,"00") & "." & TEXT($A$1,"00")) -> 0 | S21: =SUMIFS($G:$G,$H:$H,$P21,$F:$F,TEXT(S$5,"00") & "." & TEXT($A$1,"00")) -> 0 | T21: =SUMIFS($G:$G,$H:$H,$P21,$F:$F,TEXT(T$5,"00") & "." & TEXT($A$1,"00")) -> 0 | U21: =SUMIFS($G:$G,$H:$H,$P21,$F:$F,TEXT(U$5,"00") & "." & TEXT($A$1,"00")) -> 0 | V21: =SUMIFS($G:$G,$H:$H,$P21,$F:$F,TEXT(V$5,"00") & "." & TEXT($A$1,"00")) -> 0 | W21: =SUMIFS($G:$G,$H:$H,$P21,$F:$F,TEXT(W$5,"00") & "." & TEXT($A$1,"00")) -> 0 | X21: =SUMIFS($G:$G,$H:$H,$P21,$F:$F,TEXT(X$5,"00") & "." & TEXT($A$1,"00")) -> 0 | Y21: =SUMIFS($G:$G,$H:$H,$P21,$F:$F,TEXT(Y$5,"00") & "." & TEXT($A$1,"00")) -> 0 | ... AV21: =SUMIFS($G:$G,$H:$H,$P21,$F:$F,TEXT(AV$5,"00") & "." & TEXT($A$1,"00")) -> 0 | AW21: =SUM(Q21:AV21) -> 703.8
B22: קצבה | C22: 269 | G22: 122.4 | H22: טלפונים ניידים | I22: =_xlfn.XLOOKUP(H22,[2]Dropdown!B:B,[2]Dropdown!C:C) -> תחזוקת דירה ותקשורת | J22: ל-ו 2 | P22: מים | Q22: =SUMIFS($G:$G,$H:$H,$P22,$F:$F,"") -> 647 | R22: =SUMIFS($G:$G,$H:$H,$P22,$F:$F,TEXT(R$5,"00") & "." & TEXT($A$1,"00")) -> 0 | S22: =SUMIFS($G:$G,$H:$H,$P22,$F:$F,TEXT(S$5,"00") & "." & TEXT($A$1,"00")) -> 0 | T22: =SUMIFS($G:$G,$H:$H,$P22,$F:$F,TEXT(T$5,"00") & "." & TEXT($A$1,"00")) -> 0 | U22: =SUMIFS($G:$G,$H:$H,$P22,$F:$F,TEXT(U$5,"00") & "." & TEXT($A$1,"00")) -> 0 | V22: =SUMIFS($G:$G,$H:$H,$P22,$F:$F,TEXT(V$5,"00") & "." & TEXT($A$1,"00")) -> 0 | W22: =SUMIFS($G:$G,$H:$H,$P22,$F:$F,TEXT(W$5,"00") & "." & TEXT($A$1,"00")) -> 0 | X22: =SUMIFS($G:$G,$H:$H,$P22,$F:$F,TEXT(X$5,"00") & "." & TEXT($A$1,"00")) -> 0 | Y22: =SUMIFS($G:$G,$H:$H,$P22,$F:$F,TEXT(Y$5,"00") & "." & TEXT($A$1,"00")) -> 0 | ... AV22: =SUMIFS($G:$G,$H:$H,$P22,$F:$F,TEXT(AV$5,"00") & "." & TEXT($A$1,"00")) -> 0 | AW22: =SUM(Q22:AV22) -> 647
B23: עסק | C23: 700 | G23: 80.55 | H23: ביטוח בריאות פרטי | I23: =_xlfn.XLOOKUP(H23,[2]Dropdown!B:B,[2]Dropdown!C:C) -> בריאות וטיפולים | J23: ל-ו 2 | M23: מנורה | P23: חשמל | Q23: =SUMIFS($G:$G,$H:$H,$P23,$F:$F,"") -> 689.66 | R23: =SUMIFS($G:$G,$H:$H,$P23,$F:$F,TEXT(R$5,"00") & "." & TEXT($A$1,"00")) -> 0 | S23: =SUMIFS($G:$G,$H:$H,$P23,$F:$F,TEXT(S$5,"00") & "." & TEXT($A$1,"00")) -> 0 | T23: =SUMIFS($G:$G,$H:$H,$P23,$F:$F,TEXT(T$5,"00") & "." & TEXT($A$1,"00")) -> 0 | U23: =SUMIFS($G:$G,$H:$H,$P23,$F:$F,TEXT(U$5,"00") & "." & TEXT($A$1,"00")) -> 0 | V23: =SUMIFS($G:$G,$H:$H,$P23,$F:$F,TEXT(V$5,"00") & "." & TEXT($A$1,"00")) -> 0 | W23: =SUMIFS($G:$G,$H:$H,$P23,$F:$F,TEXT(W$5,"00") & "." & TEXT($A$1,"00")) -> 0 | X23: =SUMIFS($G:$G,$H:$H,$P23,$F:$F,TEXT(X$5,"00") & "." & TEXT($A$1,"00")) -> 0 | Y23: =SUMIFS($G:$G,$H:$H,$P23,$F:$F,TEXT(Y$5,"00") & "." & TEXT($A$1,"00")) -> 0 | ... AV23: =SUMIFS($G:$G,$H:$H,$P23,$F:$F,TEXT(AV$5,"00") & "." & TEXT($A$1,"00")) -> 0 | AW23: =SUM(Q23:AV23) -> 689.66
A24: סה"כ | C24: 31103.42 | D24: 50708 | G24: 10.47 | H24: ביטוח בריאות פרטי | I24: =_xlfn.XLOOKUP(H24,[2]Dropdown!B:B,[2]Dropdown!C:C) -> בריאות וטיפולים | J24: ל-ו 2 | M24: הראל | P24: גז/נפט | Q24: =SUMIFS($G:$G,$H:$H,$P24,$F:$F,"") -> 0 | R24: =SUMIFS($G:$G,$H:$H,$P24,$F:$F,TEXT(R$5,"00") & "." & TEXT($A$1,"00")) -> 0 | S24: =SUMIFS($G:$G,$H:$H,$P24,$F:$F,TEXT(S$5,"00") & "." & TEXT($A$1,"00")) -> 0 | T24: =SUMIFS($G:$G,$H:$H,$P24,$F:$F,TEXT(T$5,"00") & "." & TEXT($A$1,"00")) -> 0 | U24: =SUMIFS($G:$G,$H:$H,$P24,$F:$F,TEXT(U$5,"00") & "." & TEXT($A$1,"00")) -> 0 | V24: =SUMIFS($G:$G,$H:$H,$P24,$F:$F,TEXT(V$5,"00") & "." & TEXT($A$1,"00")) -> 0 | W24: =SUMIFS($G:$G,$H:$H,$P24,$F:$F,TEXT(W$5,"00") & "." & TEXT($A$1,"00")) -> 0 | X24: =SUMIFS($G:$G,$H:$H,$P24,$F:$F,TEXT(X$5,"00") & "." & TEXT($A$1,"00")) -> 0 | Y24: =SUMIFS($G:$G,$H:$H,$P24,$F:$F,TEXT(Y$5,"00") & "." & TEXT($A$1,"00")) -> 0 | ... AV24: =SUMIFS($G:$G,$H:$H,$P24,$F:$F,TEXT(AV$5,"00") & "." & TEXT($A$1,"00")) -> 0 | AW24: =SUM(Q24:AV24) -> 0
A25: אחרות | B25: אחרות | D25: 700 | G25: 54.16 | H25: ביטוח בריאות פרטי | I25: =_xlfn.XLOOKUP(H25,[2]Dropdown!B:B,[2]Dropdown!C:C) -> בריאות וטיפולים | J25: ל-ו 2 | M25: הראל | P25: טלפון (נייח) | Q25: =SUMIFS($G:$G,$H:$H,$P25,$F:$F,"") -> 0 | R25: =SUMIFS($G:$G,$H:$H,$P25,$F:$F,TEXT(R$5,"00") & "." & TEXT($A$1,"00")) -> 0 | S25: =SUMIFS($G:$G,$H:$H,$P25,$F:$F,TEXT(S$5,"00") & "." & TEXT($A$1,"00")) -> 0 | T25: =SUMIFS($G:$G,$H:$H,$P25,$F:$F,TEXT(T$5,"00") & "." & TEXT($A$1,"00")) -> 0 | U25: =SUMIFS($G:$G,$H:$H,$P25,$F:$F,TEXT(U$5,"00") & "." & TEXT($A$1,"00")) -> 0 | V25: =SUMIFS($G:$G,$H:$H,$P25,$F:$F,TEXT(V$5,"00") & "." & TEXT($A$1,"00")) -> 0 | W25: =SUMIFS($G:$G,$H:$H,$P25,$F:$F,TEXT(W$5,"00") & "." & TEXT($A$1,"00")) -> 0 | X25: =SUMIFS($G:$G,$H:$H,$P25,$F:$F,TEXT(X$5,"00") & "." & TEXT($A$1,"00")) -> 0 | Y25: =SUMIFS($G:$G,$H:$H,$P25,$F:$F,TEXT(Y$5,"00") & "." & TEXT($A$1,"00")) -> 0 | ... AV25: =SUMIFS($G:$G,$H:$H,$P25,$F:$F,TEXT(AV$5,"00") & "." & TEXT($A$1,"00")) -> 0 | AW25: =SUM(Q25:AV25) -> 0
A26: סך הכנסות | C26: 31103.42 | D26: 51408 | G26: 259.74 | H26: ביטוח בריאות פרטי | I26: =_xlfn.XLOOKUP(H26,[2]Dropdown!B:B,[2]Dropdown!C:C) -> בריאות וטיפולים | J26: ל-ו 2 | M26: הראל | P26: טלפונים ניידים | Q26: =SUMIFS($G:$G,$H:$H,$P26,$F:$F,"") -> 122.4 | R26: =SUMIFS($G:$G,$H:$H,$P26,$F:$F,TEXT(R$5,"00") & "." & TEXT($A$1,"00")) -> 0 | S26: =SUMIFS($G:$G,$H:$H,$P26,$F:$F,TEXT(S$5,"00") & "." & TEXT($A$1,"00")) -> 0 | T26: =SUMIFS($G:$G,$H:$H,$P26,$F:$F,TEXT(T$5,"00") & "." & TEXT($A$1,"00")) -> 0 | U26: =SUMIFS($G:$G,$H:$H,$P26,$F:$F,TEXT(U$5,"00") & "." & TEXT($A$1,"00")) -> 0 | V26: =SUMIFS($G:$G,$H:$H,$P26,$F:$F,TEXT(V$5,"00") & "." & TEXT($A$1,"00")) -> 0 | W26: =SUMIFS($G:$G,$H:$H,$P26,$F:$F,TEXT(W$5,"00") & "." & TEXT($A$1,"00")) -> 0 | X26: =SUMIFS($G:$G,$H:$H,$P26,$F:$F,TEXT(X$5,"00") & "." & TEXT($A$1,"00")) -> 0 | Y26: =SUMIFS($G:$G,$H:$H,$P26,$F:$F,TEXT(Y$5,"00") & "." & TEXT($A$1,"00")) -> 0 | ... AV26: =SUMIFS($G:$G,$H:$H,$P26,$F:$F,TEXT(AV$5,"00") & "." & TEXT($A$1,"00")) -> 0 | AW26: =SUM(Q26:AV26) -> 122.4
G27: 275.38 | H27: קופ"ח + משלים | I27: =_xlfn.XLOOKUP(H27,[2]Dropdown!B:B,[2]Dropdown!C:C) -> בריאות וטיפולים | J27: ל-ו 2 | M27: כללית | P27: ביוב | Q27: =SUMIFS($G:$G,$H:$H,$P27,$F:$F,"") -> 371.4 | R27: =SUMIFS($G:$G,$H:$H,$P27,$F:$F,TEXT(R$5,"00") & "." & TEXT($A$1,"00")) -> 0 | S27: =SUMIFS($G:$G,$H:$H,$P27,$F:$F,TEXT(S$5,"00") & "." & TEXT($A$1,"00")) -> 0 | T27: =SUMIFS($G:$G,$H:$H,$P27,$F:$F,TEXT(T$5,"00") & "." & TEXT($A$1,"00")) -> 0 | U27: =SUMIFS($G:$G,$H:$H,$P27,$F:$F,TEXT(U$5,"00") & "." & TEXT($A$1,"00")) -> 0 | V27: =SUMIFS($G:$G,$H:$H,$P27,$F:$F,TEXT(V$5,"00") & "." & TEXT($A$1,"00")) -> 0 | W27: =SUMIFS($G:$G,$H:$H,$P27,$F:$F,TEXT(W$5,"00") & "." & TEXT($A$1,"00")) -> 0 | X27: =SUMIFS($G:$G,$H:$H,$P27,$F:$F,TEXT(X$5,"00") & "." & TEXT($A$1,"00")) -> 0 | Y27: =SUMIFS($G:$G,$H:$H,$P27,$F:$F,TEXT(Y$5,"00") & "." & TEXT($A$1,"00")) -> 0 | ... AV27: =SUMIFS($G:$G,$H:$H,$P27,$F:$F,TEXT(AV$5,"00") & "." & TEXT($A$1,"00")) -> 0 | AW27: =SUM(Q27:AV27) -> 371.4
A28: מצב חשבון | B28: יתרה חודש קודם | C28: -34248.61 | D28: 6283.91 | G28: 192.86 | H28: ביטוח בריאות פרטי | I28: =_xlfn.XLOOKUP(H28,[2]Dropdown!B:B,[2]Dropdown!C:C) -> בריאות וטיפולים | J28: י-ק 2 | P28: כבלים | Q28: =SUMIFS($G:$G,$H:$H,$P28,$F:$F,"") -> 214.62 | R28: =SUMIFS($G:$G,$H:$H,$P28,$F:$F,TEXT(R$5,"00") & "." & TEXT($A$1,"00")) -> 0 | S28: =SUMIFS($G:$G,$H:$H,$P28,$F:$F,TEXT(S$5,"00") & "." & TEXT($A$1,"00")) -> 0 | T28: =SUMIFS($G:$G,$H:$H,$P28,$F:$F,TEXT(T$5,"00") & "." & TEXT($A$1,"00")) -> 0 | U28: =SUMIFS($G:$G,$H:$H,$P28,$F:$F,TEXT(U$5,"00") & "." & TEXT($A$1,"00")) -> 0 | V28: =SUMIFS($G:$G,$H:$H,$P28,$F:$F,TEXT(V$5,"00") & "." & TEXT($A$1,"00")) -> 0 | W28: =SUMIFS($G:$G,$H:$H,$P28,$F:$F,TEXT(W$5,"00") & "." & TEXT($A$1,"00")) -> 0 | X28: =SUMIFS($G:$G,$H:$H,$P28,$F:$F,TEXT(X$5,"00") & "." & TEXT($A$1,"00")) -> 0 | Y28: =SUMIFS($G:$G,$H:$H,$P28,$F:$F,TEXT(Y$5,"00") & "." & TEXT($A$1,"00")) -> 0 | ... AV28: =SUMIFS($G:$G,$H:$H,$P28,$F:$F,TEXT(AV$5,"00") & "." & TEXT($A$1,"00")) -> 0 | AW28: =SUM(Q28:AV28) -> 214.62
